Workbook

Sheet RawScenarioInputs
B1: 2015 USD
C2: S0 | D2: S0 | E2: S1 | F2: S1 | G2: S1 | H2: S1 | I2: S2 | J2: S2 | K2: S2 | L2: S2 | M2: S2 | N2: S2 | O2: S3
B3: S0
A4: Category | B4: EU ETS price | C4: China national ETS price | D4: UK ETS price | E4: EU ETS price | F4: China national ETS price | G4: UK ETS price | H4: Global carbon price | I4: EU ETS price | J4: China national ETS price | K4: UK ETS price | L4: KSA and UAE prod subsidies | M4: EU CBAM | N4: UK CBAM | O4: Mandates/quotas (+ ETSs from S0)
A5: 2010 | B5: 17.26598 | C5: 0 | D5: 0 | E5: 17.26598 | F5: 0 | G5: 0 | I5: 17.26598 | J5: 0 | K5: 0
A6: 2011 | B6: 23.75688 | C6: 0 | D6: 0 | E6: 23.75688 | F6: 0 | G6: 0 | I6: 23.75688 | J6: 0 | K6: 0
A7: 2012 | B7: 9.322488 | C7: 0 | D7: 0 | E7: 9.322488 | F7: 0 | G7: 0 | I7: 9.322488 | J7: 0 | K7: 0
A8: 2013 | B8: 6.04396 | C8: 0 | D8: 0 | E8: 6.04396 | F8: 0 | G8: 0 | I8: 6.04396 | J8: 0 | K8: 0
A9: 2014 | B9: 6.7571 | C9: 0 | D9: 0 | E9: 6.7571 | F9: 0 | G9: 0 | I9: 6.7571 | J9: 0 | K9: 0
A10: 2015 | B10: 7.689825 | C10: 0 | D10: 0 | E10: 7.689825 | F10: 0 | G10: 0 | I10: 7.689825 | J10: 0 | K10: 0
A11: 2016 | B11: 5.921776 | C11: 0 | D11: 0 | E11: 5.921776 | F11: 0 | G11: 0 | I11: 5.921776 | J11: 0 | K11: 0
A12: 2017 | B12: 5.644848 | C12: 0 | D12: 0 | E12: 5.644848 | F12: 0 | G12: 0 | I12: 5.644848 | J12: 0 | K12: 0
A13: 2018 | B13: 16.26372 | C13: 0 | D13: 0 | E13: 16.26372 | F13: 0 | G13: 0 | I13: 16.26372 | J13: 0 | K13: 0
A14: 2019 | B14: 24.50572 | C14: 0 | D14: 0 | E14: 24.50572 | F14: 0 | G14: 0 | I14: 24.50572 | J14: 0 | K14: 0
A15: 2020 | B15: 18.53652 | C15: 0 | D15: 0 | E15: 18.53652 | F15: 0 | G15: 0 | I15: 18.53652 | J15: 0 | K15: 0
A16: 2021 | B16: 49.77955 | C16: 0 | D16: 0 | E16: 49.77955 | F16: 0 | G16: 0 | I16: 49.77955 | J16: 0 | K16: 0
... A19: 2024 | B19: 61.30155 | C19: 0 | D19: 45.06168 | E19: 61.30155 | F19: 0 | G19: 45.06168 | I19: 61.30155 | J19: 0 | K19: 45.06168
A20: 2025 | B20: 70.37012 | C20: 0 | D20: 57.22781 | E20: 70.37012 | F20: 0 | G20: 57.22781 | H20: 0 | I20: 70.37012 | J20: 0 | K20: 57.22781 | L20: 0 | M20: 70.37012 | N20: 57.22781 | O20: 0
A21: 2026 | B21: 74.515315 | C21: 0 | D21: 61.446698 | E21: 74.515315 | G21: 61.446698 | H21: 8 | J21: 0 | L21: 0.4 | M21: 74.51532 | N21: 61.4467 | O21: 0.02
A22: 2027 | B22: 78.66051 | C22: 11.76462 | D22: 65.665585 | E22: 78.66051 | G22: 65.665585 | H22: 16 | J22: 11.76462 | L22: 0.4 | M22: 78.66051 | N22: 65.66559 | O22: 0.04
A23: 2028 | B23: 82.805706 | C23: 12.707897 | D23: 69.884473 | E23: 82.805706 | G23: 69.884473 | H23: 24 | J23: 12.707897 | L23: 0.4 | M23: 82.80571 | N23: 69.88447 | O23: 0.06
A24: 2029 | B24: 86.950901 | C24: 13.651175 | D24: 74.10336 | E24: 86.950901 | G24: 74.10336 | H24: 32 | J24: 13.651175 | L24: 0.4 | M24: 86.9509 | N24: 74.10336 | O24: 0.08
A25: 2030 | B25: 91.096096 | C25: 14.594452 | D25: 78.322248 | E25: 91.096096 | G25: 78.322248 | H25: 40 | J25: 14.594452 | L25: 0.4 | M25: 91.0961 | N25: 78.32225 | O25: 0.1
A26: 2031 | B26: 95.241291 | C26: 15.53773 | D26: 82.541136 | E26: 95.241291 | G26: 82.541136 | H26: 48 | J26: 15.53773 | L26: 0.4 | M26: 95.24129 | N26: 82.54114 | O26: 0.12
A27: 2032 | B27: 99.386486 | C27: 16.481007 | D27: 86.760023 | E27: 99.386486 | G27: 86.760023 | H27: 56 | J27: 16.481007 | L27: 0.4 | M27: 99.38649 | N27: 86.76002 | O27: 0.14
A28: 2033 | B28: 103.53168 | C28: 17.424284 | D28: 90.978911 | E28: 103.53168 | G28: 90.978911 | H28: 64 | J28: 17.424284 | L28: 0.4 | M28: 103.5317 | N28: 90.97891 | O28: 0.16
A29: 2034 | B29: 107.67688 | C29: 18.367562 | D29: 95.197798 | E29: 107.67688 | G29: 95.197798 | H29: 72 | J29: 18.367562 | L29: 0.4 | M29: 107.6769 | N29: 95.1978 | O29: 0.18
A30: 2035 | B30: 111.82207 | C30: 19.310839 | D30: 99.416686 | E30: 111.82207 | G30: 99.416686 | H30: 80 | J30: 19.310839 | L30: 0.4 | M30: 111.8221 | N30: 99.41669 | O30: 0.2
A31: 2036 | B31: 115.96727 | C31: 20.254116 | D31: 103.63557 | E31: 115.96727 | G31: 103.63557 | H31: 88 | J31: 20.254117 | L31: 0.4 | M31: 115.9673 | N31: 103.6356 | O31: 0.22
A32: 2037 | B32: 120.11246 | C32: 21.197394 | D32: 107.85446 | E32: 120.11246 | G32: 107.85446 | H32: 96 | J32: 21.197394 | L32: 0 | M32: 120.1125 | N32: 107.8545 | O32: 0.24
... A35: 2040 | B35: 132.54805 | C35: 24.027226 | D35: 120.51112 | E35: 132.54805 | G35: 120.51112 | H35: 120 | J35: 24.027226 | L35: 0 | M35: 132.548 | N35: 120.5111 | O35: 0.3
A36: 2041 | B36: 136.69324 | C36: 24.970503 | D36: 124.73001 | E36: 136.69324 | H36: 128 | J36: 24.970503 | L36: 0 | M36: 136.6932 | N36: 124.73 | O36: 0.32
A37: 2042 | B37: 140.83844 | C37: 25.913781 | D37: 128.9489 | E37: 140.83844 | H37: 136 | J37: 25.913781 | L37: 0 | M37: 140.8384 | N37: 128.9489 | O37: 0.34
A38: 2043 | B38: 144.98363 | C38: 26.857058 | D38: 133.16779 | E38: 144.98363 | H38: 144 | J38: 26.857058 | L38: 0 | M38: 144.9836 | N38: 133.1678 | O38: 0.36
A39: 2044 | B39: 149.12883 | C39: 27.800336 | D39: 137.38667 | H39: 152 | J39: 27.800336 | L39: 0 | M39: 149.1288 | N39: 137.3867 | O39: 0.38
A40: 2045 | B40: 153.27402 | C40: 28.743613 | D40: 141.60556 | H40: 160 | J40: 28.743613 | L40: 0 | M40: 153.274 | N40: 141.6056 | O40: 0.4
A41: 2046 | B41: 157.41922 | C41: 29.68689 | D41: 145.82445 | H41: 168 | J41: 29.68689 | L41: 0 | M41: 157.4192 | N41: 145.8244 | O41: 0.42
A42: 2047 | B42: 161.56441 | C42: 30.630168 | D42: 150.04334 | H42: 176 | J42: 30.630168 | L42: 0 | M42: 161.5644 | N42: 150.0433 | O42: 0.44
A43: 2048 | B43: 165.70961 | C43: 31.573445 | D43: 154.26222 | H43: 184 | J43: 31.573445 | L43: 0 | M43: 165.7096 | N43: 154.2622 | O43: 0.46
A44: 2049 | B44: 169.8548 | C44: 32.516723 | D44: 158.48111 | H44: 192 | J44: 32.516723 | L44: 0 | M44: 169.8548 | N44: 158.4811 | O44: 0.48
...

Sheet ProcessedScenarioInputs
B1: 2015 USD | C1: 2021 USD | D1: 2019 USD | E1: 2023 USD
A2: Price index | B2: 1.07 | C2: 1.41 | D2: 1.17 | E2: 1.3 | F2: Relative to 2010
A3: Exchange rate index | B3: 1 | C3: 0.87 | D3: 1.03 | E3: 1.05
A4: EUR-USD exchange rate | B4: 1.11 | C4: 1.2 | D4: 1.12 | E4: 1.2
C8: S0 | D8: S0 | E8: S1 | F8: S1 | G8: S1 | H8: S1 | I8: S2 | J8: S2 | K8: S2 | L8: S2 | M8: S2 | N8: S2 | O8: S3
B9: S0
A10: Category | B10: EU ETS price | C10: China national ETS price | D10: UK ETS price | E10: EU ETS price | F10: China national ETS price | G10: UK ETS price | H10: Global carbon price | I10: EU ETS price | J10: China national ETS price | K10: UK ETS price | L10: KSA and UAE prod subsidies | M10: EU CBAM | N10: UK CBAM | O10: Mandates/quotas (+ ETSs from S0) | R10: EU ETS price | S10: China national ETS price | T10: UK ETS price
A11: 2010 | B11: =RawScenarioInputs!B5*ProcessedScenarioInputs!B$4/(ProcessedScenarioInputs!B$2/ProcessedScenarioInputs!B$3) -> 17.911437 | C11: =RawScenarioInputs!C5*ProcessedScenarioInputs!C$4/(ProcessedScenarioInputs!C$2/ProcessedScenarioInputs!C$3) -> 0 | D11: =RawScenarioInputs!D5*ProcessedScenarioInputs!D$4/(ProcessedScenarioInputs!D$2/ProcessedScenarioInputs!D$3) -> 0 | E11: =MAX(B11,$H11) -> 17.911437 | F11: =MAX(C11,$H11) -> 0 | G11: =MAX(D11,$H11) -> 0 | I11: 17.26598 | J11: 0 | K11: 0 | R11: 17.911437 | S11: 0 | T11: 0
A12: 2011 | B12: =RawScenarioInputs!B6*ProcessedScenarioInputs!B$4/(ProcessedScenarioInputs!B$2/ProcessedScenarioInputs!B$3) -> 24.644988 | C12: =RawScenarioInputs!C6*ProcessedScenarioInputs!C$4/(ProcessedScenarioInputs!C$2/ProcessedScenarioInputs!C$3) -> 0 | D12: =RawScenarioInputs!D6*ProcessedScenarioInputs!D$4/(ProcessedScenarioInputs!D$2/ProcessedScenarioInputs!D$3) -> 0 | E12: =MAX(B12,$H12) -> 24.644988 | F12: =MAX(C12,$H12) -> 0 | G12: =MAX(D12,$H12) -> 0 | I12: 23.75688 | J12: 0 | K12: 0 | R12: 24.644988 | S12: 0 | T12: 0
A13: 2012 | B13: =RawScenarioInputs!B7*ProcessedScenarioInputs!B$4/(ProcessedScenarioInputs!B$2/ProcessedScenarioInputs!B$3) -> 9.6709922 | C13: =RawScenarioInputs!C7*ProcessedScenarioInputs!C$4/(ProcessedScenarioInputs!C$2/ProcessedScenarioInputs!C$3) -> 0 | D13: =RawScenarioInputs!D7*ProcessedScenarioInputs!D$4/(ProcessedScenarioInputs!D$2/ProcessedScenarioInputs!D$3) -> 0 | E13: =MAX(B13,$H13) -> 9.6709922 | F13: =MAX(C13,$H13) -> 0 | G13: =MAX(D13,$H13) -> 0 | I13: 9.322488 | J13: 0 | K13: 0 | R13: 9.6709922 | S13: 0 | T13: 0
A14: 2013 | B14: =RawScenarioInputs!B8*ProcessedScenarioInputs!B$4/(ProcessedScenarioInputs!B$2/ProcessedScenarioInputs!B$3) -> 6.2699024 | C14: =RawScenarioInputs!C8*ProcessedScenarioInputs!C$4/(ProcessedScenarioInputs!C$2/ProcessedScenarioInputs!C$3) -> 0 | D14: =RawScenarioInputs!D8*ProcessedScenarioInputs!D$4/(ProcessedScenarioInputs!D$2/ProcessedScenarioInputs!D$3) -> 0 | E14: =MAX(B14,$H14) -> 6.2699024 | F14: =MAX(C14,$H14) -> 0 | G14: =MAX(D14,$H14) -> 0 | I14: 6.04396 | J14: 0 | K14: 0 | R14: 6.2699024 | S14: 0 | T14: 0
A15: 2014 | B15: =RawScenarioInputs!B9*ProcessedScenarioInputs!B$4/(ProcessedScenarioInputs!B$2/ProcessedScenarioInputs!B$3) -> 7.0097019 | C15: =RawScenarioInputs!C9*ProcessedScenarioInputs!C$4/(ProcessedScenarioInputs!C$2/ProcessedScenarioInputs!C$3) -> 0 | D15: =RawScenarioInputs!D9*ProcessedScenarioInputs!D$4/(ProcessedScenarioInputs!D$2/ProcessedScenarioInputs!D$3) -> 0 | E15: =MAX(B15,$H15) -> 7.0097019 | F15: =MAX(C15,$H15) -> 0 | G15: =MAX(D15,$H15) -> 0 | I15: 6.7571 | J15: 0 | K15: 0 | R15: 7.0097019 | S15: 0 | T15: 0
A16: 2015 | B16: =RawScenarioInputs!B10*ProcessedScenarioInputs!B$4/(ProcessedScenarioInputs!B$2/ProcessedScenarioInputs!B$3) -> 7.9772951 | C16: =RawScenarioInputs!C10*ProcessedScenarioInputs!C$4/(ProcessedScenarioInputs!C$2/ProcessedScenarioInputs!C$3) -> 0 | D16: =RawScenarioInputs!D10*ProcessedScenarioInputs!D$4/(ProcessedScenarioInputs!D$2/ProcessedScenarioInputs!D$3) -> 0 | E16: =MAX(B16,$H16) -> 7.9772951 | F16: =MAX(C16,$H16) -> 0 | G16: =MAX(D16,$H16) -> 0 | I16: 7.689825 | J16: 0 | K16: 0 | R16: 7.9772951 | S16: 0 | T16: 0
A17: 2016 | B17: =RawScenarioInputs!B11*ProcessedScenarioInputs!B$4/(ProcessedScenarioInputs!B$2/ProcessedScenarioInputs!B$3) -> 6.1431508 | C17: =RawScenarioInputs!C11*ProcessedScenarioInputs!C$4/(ProcessedScenarioInputs!C$2/ProcessedScenarioInputs!C$3) -> 0 | D17: =RawScenarioInputs!D11*ProcessedScenarioInputs!D$4/(ProcessedScenarioInputs!D$2/ProcessedScenarioInputs!D$3) -> 0 | E17: =MAX(B17,$H17) -> 6.1431508 | F17: =MAX(C17,$H17) -> 0 | G17: =MAX(D17,$H17) -> 0 | I17: 5.921776 | J17: 0 | K17: 0 | R17: 6.1431508 | S17: 0 | T17: 0
A18: 2017 | B18: =RawScenarioInputs!B12*ProcessedScenarioInputs!B$4/(ProcessedScenarioInputs!B$2/ProcessedScenarioInputs!B$3) -> 5.8558704 | C18: =RawScenarioInputs!C12*ProcessedScenarioInputs!C$4/(ProcessedScenarioInputs!C$2/ProcessedScenarioInputs!C$3) -> 0 | D18: =RawScenarioInputs!D12*ProcessedScenarioInputs!D$4/(ProcessedScenarioInputs!D$2/ProcessedScenarioInputs!D$3) -> 0 | E18: =MAX(B18,$H18) -> 5.8558704 | F18: =MAX(C18,$H18) -> 0 | G18: =MAX(D18,$H18) -> 0 | I18: 5.644848 | J18: 0 | K18: 0 | R18: 5.8558704 | S18: 0 | T18: 0
A19: 2018 | B19: =RawScenarioInputs!B13*ProcessedScenarioInputs!B$4/(ProcessedScenarioInputs!B$2/ProcessedScenarioInputs!B$3) -> 16.87171 | C19: =RawScenarioInputs!C13*ProcessedScenarioInputs!C$4/(ProcessedScenarioInputs!C$2/ProcessedScenarioInputs!C$3) -> 0 | D19: =RawScenarioInputs!D13*ProcessedScenarioInputs!D$4/(ProcessedScenarioInputs!D$2/ProcessedScenarioInputs!D$3) -> 0 | E19: =MAX(B19,$H19) -> 16.87171 | F19: =MAX(C19,$H19) -> 0 | G19: =MAX(D19,$H19) -> 0 | I19: 16.26372 | J19: 0 | K19: 0 | R19: 16.87171 | S19: 0 | T19: 0
A20: 2019 | B20: =RawScenarioInputs!B14*ProcessedScenarioInputs!B$4/(ProcessedScenarioInputs!B$2/ProcessedScenarioInputs!B$3) -> 25.421822 | C20: =RawScenarioInputs!C14*ProcessedScenarioInputs!C$4/(ProcessedScenarioInputs!C$2/ProcessedScenarioInputs!C$3) -> 0 | D20: =RawScenarioInputs!D14*ProcessedScenarioInputs!D$4/(ProcessedScenarioInputs!D$2/ProcessedScenarioInputs!D$3) -> 0 | E20: =MAX(B20,$H20) -> 25.421822 | F20: =MAX(C20,$H20) -> 0 | G20: =MAX(D20,$H20) -> 0 | I20: 24.50572 | J20: 0 | K20: 0 | R20: 25.421822 | S20: 0 | T20: 0
A21: 2020 | B21: =RawScenarioInputs!B15*ProcessedScenarioInputs!B$4/(ProcessedScenarioInputs!B$2/ProcessedScenarioInputs!B$3) -> 19.229474 | C21: =RawScenarioInputs!C15*ProcessedScenarioInputs!C$4/(ProcessedScenarioInputs!C$2/ProcessedScenarioInputs!C$3) -> 0 | D21: =RawScenarioInputs!D15*ProcessedScenarioInputs!D$4/(ProcessedScenarioInputs!D$2/ProcessedScenarioInputs!D$3) -> 0 | E21: =MAX(B21,$H21) -> 19.229474 | F21: =MAX(C21,$H21) -> 0 | G21: =MAX(D21,$H21) -> 0 | I21: 18.53652 | J21: 0 | K21: 0 | R21: 19.229474 | S21: 0 | T21: 0
A22: 2021 | B22: =RawScenarioInputs!B16*ProcessedScenarioInputs!B$4/(ProcessedScenarioInputs!B$2/ProcessedScenarioInputs!B$3) -> 51.640468 | C22: =RawScenarioInputs!C16*ProcessedScenarioInputs!C$4/(ProcessedScenarioInputs!C$2/ProcessedScenarioInputs!C$3) -> 0 | D22: =RawScenarioInputs!D16*ProcessedScenarioInputs!D$4/(ProcessedScenarioInputs!D$2/ProcessedScenarioInputs!D$3) -> 0 | E22: =MAX(B22,$H22) -> 51.640468 | F22: =MAX(C22,$H22) -> 0 | G22: =MAX(D22,$H22) -> 0 | I22: 49.77955 | J22: 0 | K22: 0 | R22: 51.640468 | S22: 0 | T22: 0
... A25: 2024 | B25: =RawScenarioInputs!B19*ProcessedScenarioInputs!B$4/(ProcessedScenarioInputs!B$2/ProcessedScenarioInputs!B$3) -> 63.593197 | C25: =RawScenarioInputs!C19*ProcessedScenarioInputs!C$4/(ProcessedScenarioInputs!C$2/ProcessedScenarioInputs!C$3) -> 0 | D25: =RawScenarioInputs!D19*ProcessedScenarioInputs!D$4/(ProcessedScenarioInputs!D$2/ProcessedScenarioInputs!D$3) -> 44.430046 | E25: =MAX(B25,$H25) -> 63.593197 | F25: =MAX(C25,$H25) -> 0 | G25: =MAX(D25,$H25) -> 44.430046 | I25: 61.30155 | J25: 0 | K25: 45.06168 | R25: 63.593197 | S25: 0 | T25: 44.430046
A26: 2025 | B26: =RawScenarioInputs!B20*ProcessedScenarioInputs!B$4/(ProcessedScenarioInputs!B$2/ProcessedScenarioInputs!B$3) -> 73.000779 | C26: =RawScenarioInputs!C20*ProcessedScenarioInputs!C$4/(ProcessedScenarioInputs!C$2/ProcessedScenarioInputs!C$3) -> 0 | D26: =RawScenarioInputs!D20*ProcessedScenarioInputs!D$4/(ProcessedScenarioInputs!D$2/ProcessedScenarioInputs!D$3) -> 56.425642 | E26: =MAX(B26,$H26) -> 73.000779 | F26: =MAX(C26,$H26) -> 0 | G26: =MAX(D26,$H26) -> 56.425642 | H26: =RawScenarioInputs!H20*ProcessedScenarioInputs!E$4/(ProcessedScenarioInputs!E$2/ProcessedScenarioInputs!E$3) -> 0 | I26: 70.37012 | J26: 0 | K26: 57.22781 | L26: 0 | M26: 70.37012 | N26: 57.22781 | O26: 0 | R26: 73.000779 | S26: 0 | T26: 56.425642
A27: 2026 | B27: =RawScenarioInputs!B21*ProcessedScenarioInputs!B$4/(ProcessedScenarioInputs!B$2/ProcessedScenarioInputs!B$3) -> 77.300934 | C27: =RawScenarioInputs!C21*ProcessedScenarioInputs!C$4/(ProcessedScenarioInputs!C$2/ProcessedScenarioInputs!C$3) -> 0 | D27: =RawScenarioInputs!D21*ProcessedScenarioInputs!D$4/(ProcessedScenarioInputs!D$2/ProcessedScenarioInputs!D$3) -> 60.585394 | E27: =MAX(B27,$H27) -> 77.300934 | F27: =MAX(C27,$H27) -> 7.7538462 | G27: =MAX(D27,$H27) -> 60.585394 | H27: =RawScenarioInputs!H21*ProcessedScenarioInputs!E$4/(ProcessedScenarioInputs!E$2/ProcessedScenarioInputs!E$3) -> 7.7538462 | J27: 0 | L27: 0.4 | M27: 74.51532 | N27: 61.4467 | O27: 0.02 | R27: 77.300934 | S27: 0 | T27: 60.585394
A28: 2027 | B28: =RawScenarioInputs!B22*ProcessedScenarioInputs!B$4/(ProcessedScenarioInputs!B$2/ProcessedScenarioInputs!B$3) -> 81.60109 | C28: =RawScenarioInputs!C22*ProcessedScenarioInputs!C$4/(ProcessedScenarioInputs!C$2/ProcessedScenarioInputs!C$3) -> 8.710825 | D28: =RawScenarioInputs!D22*ProcessedScenarioInputs!D$4/(ProcessedScenarioInputs!D$2/ProcessedScenarioInputs!D$3) -> 64.745144 | E28: =MAX(B28,$H28) -> 81.60109 | F28: =MAX(C28,$H28) -> 15.507692 | G28: =MAX(D28,$H28) -> 64.745144 | H28: =RawScenarioInputs!H22*ProcessedScenarioInputs!E$4/(ProcessedScenarioInputs!E$2/ProcessedScenarioInputs!E$3) -> 15.507692 | J28: 11.76462 | L28: 0.4 | M28: 78.66051 | N28: 65.66559 | O28: 0.04 | R28: 81.60109 | S28: 8.710825 | T28: 64.745144 | W28: 0
A29: 2028 | B29: =RawScenarioInputs!B23*ProcessedScenarioInputs!B$4/(ProcessedScenarioInputs!B$2/ProcessedScenarioInputs!B$3) -> 85.901246 | C29: =RawScenarioInputs!C23*ProcessedScenarioInputs!C$4/(ProcessedScenarioInputs!C$2/ProcessedScenarioInputs!C$3) -> 9.4092517 | D29: =RawScenarioInputs!D23*ProcessedScenarioInputs!D$4/(ProcessedScenarioInputs!D$2/ProcessedScenarioInputs!D$3) -> 68.904896 | E29: =MAX(B29,$H29) -> 85.901246 | F29: =MAX(C29,$H29) -> 23.261538 | G29: =MAX(D29,$H29) -> 68.904896 | H29: =RawScenarioInputs!H23*ProcessedScenarioInputs!E$4/(ProcessedScenarioInputs!E$2/ProcessedScenarioInputs!E$3) -> 23.261538 | J29: 12.707897 | L29: 0.4 | M29: 82.80571 | N29: 69.88447 | O29: 0.06 | R29: 85.901246 | S29: 9.4092517 | T29: 68.904896 | W29: 7.7538462
A30: 2029 | B30: =RawScenarioInputs!B24*ProcessedScenarioInputs!B$4/(ProcessedScenarioInputs!B$2/ProcessedScenarioInputs!B$3) -> 90.201402 | C30: =RawScenarioInputs!C24*ProcessedScenarioInputs!C$4/(ProcessedScenarioInputs!C$2/ProcessedScenarioInputs!C$3) -> 10.107678 | D30: =RawScenarioInputs!D24*ProcessedScenarioInputs!D$4/(ProcessedScenarioInputs!D$2/ProcessedScenarioInputs!D$3) -> 73.064646 | E30: =MAX(B30,$H30) -> 90.201402 | F30: =MAX(C30,$H30) -> 31.015385 | G30: =MAX(D30,$H30) -> 73.064646 | H30: =RawScenarioInputs!H24*ProcessedScenarioInputs!E$4/(ProcessedScenarioInputs!E$2/ProcessedScenarioInputs!E$3) -> 31.015385 | J30: 13.651175 | L30: 0.4 | M30: 86.9509 | N30: 74.10336 | O30: 0.08 | R30: 90.201402 | S30: 10.107678 | T30: 73.064646 | W30: 15.507692
A31: 2030 | B31: =RawScenarioInputs!B25*ProcessedScenarioInputs!B$4/(ProcessedScenarioInputs!B$2/ProcessedScenarioInputs!B$3) -> 94.501558 | C31: =RawScenarioInputs!C25*ProcessedScenarioInputs!C$4/(ProcessedScenarioInputs!C$2/ProcessedScenarioInputs!C$3) -> 10.806105 | D31: =RawScenarioInputs!D25*ProcessedScenarioInputs!D$4/(ProcessedScenarioInputs!D$2/ProcessedScenarioInputs!D$3) -> 77.224398 | E31: =MAX(B31,$H31) -> 94.501558 | F31: =MAX(C31,$H31) -> 38.769231 | G31: =MAX(D31,$H31) -> 77.224398 | H31: =RawScenarioInputs!H25*ProcessedScenarioInputs!E$4/(ProcessedScenarioInputs!E$2/ProcessedScenarioInputs!E$3) -> 38.769231 | J31: 14.594452 | L31: 0.4 | M31: 91.0961 | N31: 78.32225 | O31: 0.1 | R31: 94.501558 | S31: 10.806105 | T31: 77.224398 | W31: 23.261538
A32: 2031 | B32: =RawScenarioInputs!B26*ProcessedScenarioInputs!B$4/(ProcessedScenarioInputs!B$2/ProcessedScenarioInputs!B$3) -> 98.801713 | C32: =RawScenarioInputs!C26*ProcessedScenarioInputs!C$4/(ProcessedScenarioInputs!C$2/ProcessedScenarioInputs!C$3) -> 11.504532 | D32: =RawScenarioInputs!D26*ProcessedScenarioInputs!D$4/(ProcessedScenarioInputs!D$2/ProcessedScenarioInputs!D$3) -> 81.384149 | E32: =MAX(B32,$H32) -> 98.801713 | F32: =MAX(C32,$H32) -> 46.523077 | G32: =MAX(D32,$H32) -> 81.384149 | H32: =RawScenarioInputs!H26*ProcessedScenarioInputs!E$4/(ProcessedScenarioInputs!E$2/ProcessedScenarioInputs!E$3) -> 46.523077 | J32: 15.53773 | L32: 0.4 | M32: 95.24129 | N32: 82.54114 | O32: 0.12 | R32: 98.801713 | S32: 11.504532 | T32: 81.384149 | W32: 31.015385
A33: 2032 | B33: =RawScenarioInputs!B27*ProcessedScenarioInputs!B$4/(ProcessedScenarioInputs!B$2/ProcessedScenarioInputs!B$3) -> 103.10187 | C33: =RawScenarioInputs!C27*ProcessedScenarioInputs!C$4/(ProcessedScenarioInputs!C$2/ProcessedScenarioInputs!C$3) -> 12.202958 | D33: =RawScenarioInputs!D27*ProcessedScenarioInputs!D$4/(ProcessedScenarioInputs!D$2/ProcessedScenarioInputs!D$3) -> 85.5439 | E33: =MAX(B33,$H33) -> 103.10187 | F33: =MAX(C33,$H33) -> 54.276923 | G33: =MAX(D33,$H33) -> 85.5439 | H33: =RawScenarioInputs!H27*ProcessedScenarioInputs!E$4/(ProcessedScenarioInputs!E$2/ProcessedScenarioInputs!E$3) -> 54.276923 | J33: 16.481007 | L33: 0.4 | M33: 99.38649 | N33: 86.76002 | O33: 0.14 | R33: 103.10187 | S33: 12.202958 | T33: 85.5439 | W33: 38.769231
A34: 2033 | B34: =RawScenarioInputs!B28*ProcessedScenarioInputs!B$4/(ProcessedScenarioInputs!B$2/ProcessedScenarioInputs!B$3) -> 107.40202 | C34: =RawScenarioInputs!C28*ProcessedScenarioInputs!C$4/(ProcessedScenarioInputs!C$2/ProcessedScenarioInputs!C$3) -> 12.901385 | D34: =RawScenarioInputs!D28*ProcessedScenarioInputs!D$4/(ProcessedScenarioInputs!D$2/ProcessedScenarioInputs!D$3) -> 89.703651 | E34: =MAX(B34,$H34) -> 107.40202 | F34: =MAX(C34,$H34) -> 62.030769 | G34: =MAX(D34,$H34) -> 89.703651 | H34: =RawScenarioInputs!H28*ProcessedScenarioInputs!E$4/(ProcessedScenarioInputs!E$2/ProcessedScenarioInputs!E$3) -> 62.030769 | J34: 17.424284 | L34: 0.4 | M34: 103.5317 | N34: 90.97891 | O34: 0.16 | R34: 107.40202 | S34: 12.901385 | T34: 89.703651 | W34: 46.523077
A35: 2034 | B35: =RawScenarioInputs!B29*ProcessedScenarioInputs!B$4/(ProcessedScenarioInputs!B$2/ProcessedScenarioInputs!B$3) -> 111.70218 | C35: =RawScenarioInputs!C29*ProcessedScenarioInputs!C$4/(ProcessedScenarioInputs!C$2/ProcessedScenarioInputs!C$3) -> 13.599812 | D35: =RawScenarioInputs!D29*ProcessedScenarioInputs!D$4/(ProcessedScenarioInputs!D$2/ProcessedScenarioInputs!D$3) -> 93.863402 | E35: =MAX(B35,$H35) -> 111.70218 | F35: =MAX(C35,$H35) -> 69.784615 | G35: =MAX(D35,$H35) -> 93.863402 | H35: =RawScenarioInputs!H29*ProcessedScenarioInputs!E$4/(ProcessedScenarioInputs!E$2/ProcessedScenarioInputs!E$3) -> 69.784615 | J35: 18.367562 | L35: 0.4 | M35: 107.6769 | N35: 95.1978 | O35: 0.18 | R35: 111.70218 | S35: 13.599812 | T35: 93.863402 | W35: 54.276923
A36: 2035 | B36: =RawScenarioInputs!B30*ProcessedScenarioInputs!B$4/(ProcessedScenarioInputs!B$2/ProcessedScenarioInputs!B$3) -> 116.00233 | C36: =RawScenarioInputs!C30*ProcessedScenarioInputs!C$4/(ProcessedScenarioInputs!C$2/ProcessedScenarioInputs!C$3) -> 14.298238 | D36: =RawScenarioInputs!D30*ProcessedScenarioInputs!D$4/(ProcessedScenarioInputs!D$2/ProcessedScenarioInputs!D$3) -> 98.023153 | E36: =MAX(B36,$H36) -> 116.00233 | F36: =MAX(C36,$H36) -> 77.538462 | G36: =MAX(D36,$H36) -> 98.023153 | H36: =RawScenarioInputs!H30*ProcessedScenarioInputs!E$4/(ProcessedScenarioInputs!E$2/ProcessedScenarioInputs!E$3) -> 77.538462 | J36: 19.310839 | L36: 0.4 | M36: 111.8221 | N36: 99.41669 | O36: 0.2 | R36: 116.00233 | S36: 14.298238 | T36: 98.023153 | W36: 62.030769
A37: 2036 | B37: =RawScenarioInputs!B31*ProcessedScenarioInputs!B$4/(ProcessedScenarioInputs!B$2/ProcessedScenarioInputs!B$3) -> 120.3025 | C37: =RawScenarioInputs!C31*ProcessedScenarioInputs!C$4/(ProcessedScenarioInputs!C$2/ProcessedScenarioInputs!C$3) -> 14.996665 | D37: =RawScenarioInputs!D31*ProcessedScenarioInputs!D$4/(ProcessedScenarioInputs!D$2/ProcessedScenarioInputs!D$3) -> 102.1829 | E37: =MAX(B37,$H37) -> 120.3025 | F37: =MAX(C37,$H37) -> 85.292308 | G37: =MAX(D37,$H37) -> 102.1829 | H37: =RawScenarioInputs!H31*ProcessedScenarioInputs!E$4/(ProcessedScenarioInputs!E$2/ProcessedScenarioInputs!E$3) -> 85.292308 | J37: 20.254117 | L37: 0.4 | M37: 115.9673 | N37: 103.6356 | O37: 0.22 | R37: 120.3025 | S37: 14.996665 | T37: 102.1829 | W37: 69.784615
A38: 2037 | B38: =RawScenarioInputs!B32*ProcessedScenarioInputs!B$4/(ProcessedScenarioInputs!B$2/ProcessedScenarioInputs!B$3) -> 124.60265 | C38: =RawScenarioInputs!C32*ProcessedScenarioInputs!C$4/(ProcessedScenarioInputs!C$2/ProcessedScenarioInputs!C$3) -> 15.695092 | D38: =RawScenarioInputs!D32*ProcessedScenarioInputs!D$4/(ProcessedScenarioInputs!D$2/ProcessedScenarioInputs!D$3) -> 106.34265 | E38: =MAX(B38,$H38) -> 124.60265 | F38: =MAX(C38,$H38) -> 93.046154 | G38: =MAX(D38,$H38) -> 106.34265 | H38: =RawScenarioInputs!H32*ProcessedScenarioInputs!E$4/(ProcessedScenarioInputs!E$2/ProcessedScenarioInputs!E$3) -> 93.046154 | J38: 21.197394 | L38: 0 | M38: 120.1125 | N38: 107.8545 | O38: 0.24 | R38: 124.60265 | S38: 15.695092 | T38: 106.34265 | W38: 77.538462
A39: 2038 | B39: =RawScenarioInputs!B33*ProcessedScenarioInputs!B$4/(ProcessedScenarioInputs!B$2/ProcessedScenarioInputs!B$3) -> 128.90281 | C39: =RawScenarioInputs!C33*ProcessedScenarioInputs!C$4/(ProcessedScenarioInputs!C$2/ProcessedScenarioInputs!C$3) -> 16.393518 | D39: =RawScenarioInputs!D33*ProcessedScenarioInputs!D$4/(ProcessedScenarioInputs!D$2/ProcessedScenarioInputs!D$3) -> 110.50241 | E39: =MAX(B39,$H39) -> 128.90281 | F39: =MAX(C39,$H39) -> 100.8 | G39: =MAX(D39,$H39) -> 110.50241 | H39: =RawScenarioInputs!H33*ProcessedScenarioInputs!E$4/(ProcessedScenarioInputs!E$2/ProcessedScenarioInputs!E$3) -> 100.8 | J39: 22.140671 | L39: 0 | M39: 124.2577 | N39: 112.0733 | O39: 0.26 | R39: 128.90281 | S39: 16.393518 | T39: 110.50241 | W39: 85.292308
... A51: 2050 | B51: =RawScenarioInputs!B45*ProcessedScenarioInputs!B$4/(ProcessedScenarioInputs!B$2/ProcessedScenarioInputs!B$3) -> 180.50467 | C51: =RawScenarioInputs!C45*ProcessedScenarioInputs!C$4/(ProcessedScenarioInputs!C$2/ProcessedScenarioInputs!C$3) -> 24.774638 | D51: =RawScenarioInputs!D45*ProcessedScenarioInputs!D$4/(ProcessedScenarioInputs!D$2/ProcessedScenarioInputs!D$3) -> 160.41942 | E51: =MAX(B51,$H51) -> 193.84615 | F51: =MAX(C51,$H51) -> 193.84615 | G51: =MAX(D51,$H51) -> 193.84615 | H51: =RawScenarioInputs!H45*ProcessedScenarioInputs!E$4/(ProcessedScenarioInputs!E$2/ProcessedScenarioInputs!E$3) -> 193.84615 | J51: 33.46 | L51: 0 | M51: 174 | N51: 162.7 | O51: 0.5 | R51: 180.50467 | S51: 24.774638 | T51: 160.41942 | W51: 178.33846
W52: 186.09231
W53: 193.84615

Sheet HYPR-S0
B1: 2001 | C1: 2002 | D1: 2003 | E1: 2004 | F1: 2005 | G1: 2006 | H1: 2007 | I1: 2008 | J1: 2009 | K1: 2010 | L1: 2011 | M1: 2012 | N1: 2013 | O1: 2014 | P1: 2015 | Q1: 2016 | R1: 2017 | S1: 2018 | T1: 2019 | U1: 2020 | V1: 2021 | W1: 2022 | X1: 2023 | Y1: 2024 | Z1: 2025 | AA1: 2026 | AB1: 2027 | AC1: 2028 | AD1: 2029 | AE1: 2030 | AF1: 2031 | AG1: 2032 | AH1: 2033 | AI1: 2034 | AJ1: 2035 | AK1: 2036 | AL1: 2037 | AM1: 2038 | AN1: 2039 | AO1: 2040 | AP1: 2041 | AQ1: 2042 | AR1: 2043 | AS1: 2044 | AT1: 2045 | AU1: 2046 | AV1: 2047 | AW1: 2048 | AX1: 2049 | AY1: 2050 | AZ1: 2051 | BA1: 2052 | BB1: 2053 | BC1: 2054 | BD1: 2055 | BE1: 2056 | BF1: 2057 | BG1: 2058 | BH1: 2059 | BI1: 2060 | BJ1: 2061 | BK1: 2062 | BL1: 2063 | BM1: 2064 | BN1: 2065 | BO1: 2066 | BP1: 2067 | BQ1: 2068 | BR1: 2069 | BS1: 2070 | BT1: 2071 | BU1: 2072 | BV1: 2073 | BW1: 2074 | BX1: 2075 | BY1: 2076 | BZ1: 2077 | CA1: 2078 | CB1: 2079 | CC1: 2080 | CD1: 2081 | CE1: 2082 | CF1: 2083 | CG1: 2084 | CH1: 2085 | CI1: 2086 | CJ1: 2087 | CK1: 2088 | CL1: 2089 | CM1: 2090 | CN1: 2091 | CO1: 2092 | CP1: 2093 | CQ1: 2094 | CR1: 2095 | CS1: 2096 | CT1: 2097 | CU1: 2098 | CV1: 2099 | CW1: 2100
A2: BE | B2: 0 | C2: 0 | D2: 0 | E2: 0 | F2: 0 | G2: 0 | H2: 0 | I2: 0 | J2: 0 | K2: 17.911437 | L2: 24.644988 | M2: 9.6709922 | N2: 6.2699024 | O2: 7.0097019 | P2: 7.9772951 | Q2: 6.1431508 | R2: 5.8558704 | S2: 16.87171 | T2: 25.421822 | U2: 19.229474 | V2: 51.640468 | W2: 89.760731 | X2: 99.89806 | Y2: 63.593197 | Z2: 73.000779 | AA2: 77.300934 | AB2: 81.60109 | AC2: 85.901246 | AD2: 90.201402 | AE2: 94.501558 | AF2: 98.801713 | AG2: 103.10187 | AH2: 107.40202 | AI2: 111.70218 | AJ2: 116.00233 | AK2: 120.3025 | AL2: 124.60265 | AM2: 128.90281 | AN2: 133.20296 | AO2: 137.50312 | AP2: 141.80327 | AQ2: 146.10343 | AR2: 150.40358 | AS2: 154.70374 | AT2: 159.00389 | AU2: 163.30405 | AV2: 167.6042 | AW2: 171.90436 | AX2: 176.20451 | AY2: 180.50467 | AZ2: 0 | BA2: 0 | BB2: 0 | BC2: 0 | BD2: 0 | BE2: 0 | BF2: 0 | BG2: 0 | BH2: 0 | BI2: 0 | BJ2: 0 | BK2: 0 | BL2: 0 | BM2: 0 | BN2: 0 | BO2: 0 | BP2: 0 | BQ2: 0 | BR2: 0 | BS2: 0 | BT2: 0 | BU2: 0 | BV2: 0 | BW2: 0 | BX2: 0 | BY2: 0 | BZ2: 0 | CA2: 0 | CB2: 0 | CC2: 0 | CD2: 0 | CE2: 0 | CF2: 0 | CG2: 0 | CH2: 0 | CI2: 0 | CJ2: 0 | CK2: 0 | CL2: 0 | CM2: 0 | CN2: 0 | CO2: 0 | CP2: 0 | CQ2: 0 | CR2: 0 | CS2: 0 | CT2: 0 | CU2: 0 | CV2: 0 | CW2: 0
A3: DK | B3: 0 | C3: 0 | D3: 0 | E3: 0 | F3: 0 | G3: 0 | H3: 0 | I3: 0 | J3: 0 | K3: 17.911437 | L3: 24.644988 | M3: 9.6709922 | N3: 6.2699024 | O3: 7.0097019 | P3: 7.9772951 | Q3: 6.1431508 | R3: 5.8558704 | S3: 16.87171 | T3: 25.421822 | U3: 19.229474 | V3: 51.640468 | W3: 89.760731 | X3: 99.89806 | Y3: 63.593197 | Z3: 73.000779 | AA3: 77.300934 | AB3: 81.60109 | AC3: 85.901246 | AD3: 90.201402 | AE3: 94.501558 | AF3: 98.801713 | AG3: 103.10187 | AH3: 107.40202 | AI3: 111.70218 | AJ3: 116.00233 | AK3: 120.3025 | AL3: 124.60265 | AM3: 128.90281 | AN3: 133.20296 | AO3: 137.50312 | AP3: 141.80327 | AQ3: 146.10343 | AR3: 150.40358 | AS3: 154.70374 | AT3: 159.00389 | AU3: 163.30405 | AV3: 167.6042 | AW3: 171.90436 | AX3: 176.20451 | AY3: 180.50467 | AZ3: 0 | BA3: 0 | BB3: 0 | BC3: 0 | BD3: 0 | BE3: 0 | BF3: 0 | BG3: 0 | BH3: 0 | BI3: 0 | BJ3: 0 | BK3: 0 | BL3: 0 | BM3: 0 | BN3: 0 | BO3: 0 | BP3: 0 | BQ3: 0 | BR3: 0 | BS3: 0 | BT3: 0 | BU3: 0 | BV3: 0 | BW3: 0 | BX3: 0 | BY3: 0 | BZ3: 0 | CA3: 0 | CB3: 0 | CC3: 0 | CD3: 0 | CE3: 0 | CF3: 0 | CG3: 0 | CH3: 0 | CI3: 0 | CJ3: 0 | CK3: 0 | CL3: 0 | CM3: 0 | CN3: 0 | CO3: 0 | CP3: 0 | CQ3: 0 | CR3: 0 | CS3: 0 | CT3: 0 | CU3: 0 | CV3: 0 | CW3: 0
A4: DE | B4: 0 | C4: 0 | D4: 0 | E4: 0 | F4: 0 | G4: 0 | H4: 0 | I4: 0 | J4: 0 | K4: 17.911437 | L4: 24.644988 | M4: 9.6709922 | N4: 6.2699024 | O4: 7.0097019 | P4: 7.9772951 | Q4: 6.1431508 | R4: 5.8558704 | S4: 16.87171 | T4: 25.421822 | U4: 19.229474 | V4: 51.640468 | W4: 89.760731 | X4: 99.89806 | Y4: 63.593197 | Z4: 73.000779 | AA4: 77.300934 | AB4: 81.60109 | AC4: 85.901246 | AD4: 90.201402 | AE4: 94.501558 | AF4: 98.801713 | AG4: 103.10187 | AH4: 107.40202 | AI4: 111.70218 | AJ4: 116.00233 | AK4: 120.3025 | AL4: 124.60265 | AM4: 128.90281 | AN4: 133.20296 | AO4: 137.50312 | AP4: 141.80327 | AQ4: 146.10343 | AR4: 150.40358 | AS4: 154.70374 | AT4: 159.00389 | AU4: 163.30405 | AV4: 167.6042 | AW4: 171.90436 | AX4: 176.20451 | AY4: 180.50467 | AZ4: 0 | BA4: 0 | BB4: 0 | BC4: 0 | BD4: 0 | BE4: 0 | BF4: 0 | BG4: 0 | BH4: 0 | BI4: 0 | BJ4: 0 | BK4: 0 | BL4: 0 | BM4: 0 | BN4: 0 | BO4: 0 | BP4: 0 | BQ4: 0 | BR4: 0 | BS4: 0 | BT4: 0 | BU4: 0 | BV4: 0 | BW4: 0 | BX4: 0 | BY4: 0 | BZ4: 0 | CA4: 0 | CB4: 0 | CC4: 0 | CD4: 0 | CE4: 0 | CF4: 0 | CG4: 0 | CH4: 0 | CI4: 0 | CJ4: 0 | CK4: 0 | CL4: 0 | CM4: 0 | CN4: 0 | CO4: 0 | CP4: 0 | CQ4: 0 | CR4: 0 | CS4: 0 | CT4: 0 | CU4: 0 | CV4: 0 | CW4: 0
A5: EL | B5: 0 | C5: 0 | D5: 0 | E5: 0 | F5: 0 | G5: 0 | H5: 0 | I5: 0 | J5: 0 | K5: 17.911437 | L5: 24.644988 | M5: 9.6709922 | N5: 6.2699024 | O5: 7.0097019 | P5: 7.9772951 | Q5: 6.1431508 | R5: 5.8558704 | S5: 16.87171 | T5: 25.421822 | U5: 19.229474 | V5: 51.640468 | W5: 89.760731 | X5: 99.89806 | Y5: 63.593197 | Z5: 73.000779 | AA5: 77.300934 | AB5: 81.60109 | AC5: 85.901246 | AD5: 90.201402 | AE5: 94.501558 | AF5: 98.801713 | AG5: 103.10187 | AH5: 107.40202 | AI5: 111.70218 | AJ5: 116.00233 | AK5: 120.3025 | AL5: 124.60265 | AM5: 128.90281 | AN5: 133.20296 | AO5: 137.50312 | AP5: 141.80327 | AQ5: 146.10343 | AR5: 150.40358 | AS5: 154.70374 | AT5: 159.00389 | AU5: 163.30405 | AV5: 167.6042 | AW5: 171.90436 | AX5: 176.20451 | AY5: 180.50467 | AZ5: 0 | BA5: 0 | BB5: 0 | BC5: 0 | BD5: 0 | BE5: 0 | BF5: 0 | BG5: 0 | BH5: 0 | BI5: 0 | BJ5: 0 | BK5: 0 | BL5: 0 | BM5: 0 | BN5: 0 | BO5: 0 | BP5: 0 | BQ5: 0 | BR5: 0 | BS5: 0 | BT5: 0 | BU5: 0 | BV5: 0 | BW5: 0 | BX5: 0 | BY5: 0 | BZ5: 0 | CA5: 0 | CB5: 0 | CC5: 0 | CD5: 0 | CE5: 0 | CF5: 0 | CG5: 0 | CH5: 0 | CI5: 0 | CJ5: 0 | CK5: 0 | CL5: 0 | CM5: 0 | CN5: 0 | CO5: 0 | CP5: 0 | CQ5: 0 | CR5: 0 | CS5: 0 | CT5: 0 | CU5: 0 | CV5: 0 | CW5: 0
A6: ES | B6: 0 | C6: 0 | D6: 0 | E6: 0 | F6: 0 | G6: 0 | H6: 0 | I6: 0 | J6: 0 | K6: 17.911437 | L6: 24.644988 | M6: 9.6709922 | N6: 6.2699024 | O6: 7.0097019 | P6: 7.9772951 | Q6: 6.1431508 | R6: 5.8558704 | S6: 16.87171 | T6: 25.421822 | U6: 19.229474 | V6: 51.640468 | W6: 89.760731 | X6: 99.89806 | Y6: 63.593197 | Z6: 73.000779 | AA6: 77.300934 | AB6: 81.60109 | AC6: 85.901246 | AD6: 90.201402 | AE6: 94.501558 | AF6: 98.801713 | AG6: 103.10187 | AH6: 107.40202 | AI6: 111.70218 | AJ6: 116.00233 | AK6: 120.3025 | AL6: 124.60265 | AM6: 128.90281 | AN6: 133.20296 | AO6: 137.50312 | AP6: 141.80327 | AQ6: 146.10343 | AR6: 150.40358 | AS6: 154.70374 | AT6: 159.00389 | AU6: 163.30405 | AV6: 167.6042 | AW6: 171.90436 | AX6: 176.20451 | AY6: 180.50467 | AZ6: 0 | BA6: 0 | BB6: 0 | BC6: 0 | BD6: 0 | BE6: 0 | BF6: 0 | BG6: 0 | BH6: 0 | BI6: 0 | BJ6: 0 | BK6: 0 | BL6: 0 | BM6: 0 | BN6: 0 | BO6: 0 | BP6: 0 | BQ6: 0 | BR6: 0 | BS6: 0 | BT6: 0 | BU6: 0 | BV6: 0 | BW6: 0 | BX6: 0 | BY6: 0 | BZ6: 0 | CA6: 0 | CB6: 0 | CC6: 0 | CD6: 0 | CE6: 0 | CF6: 0 | CG6: 0 | CH6: 0 | CI6: 0 | CJ6: 0 | CK6: 0 | CL6: 0 | CM6: 0 | CN6: 0 | CO6: 0 | CP6: 0 | CQ6: 0 | CR6: 0 | CS6: 0 | CT6: 0 | CU6: 0 | CV6: 0 | CW6: 0
A7: FR | B7: 0 | C7: 0 | D7: 0 | E7: 0 | F7: 0 | G7: 0 | H7: 0 | I7: 0 | J7: 0 | K7: 17.911437 | L7: 24.644988 | M7: 9.6709922 | N7: 6.2699024 | O7: 7.0097019 | P7: 7.9772951 | Q7: 6.1431508 | R7: 5.8558704 | S7: 16.87171 | T7: 25.421822 | U7: 19.229474 | V7: 51.640468 | W7: 89.760731 | X7: 99.89806 | Y7: 63.593197 | Z7: 73.000779 | AA7: 77.300934 | AB7: 81.60109 | AC7: 85.901246 | AD7: 90.201402 | AE7: 94.501558 | AF7: 98.801713 | AG7: 103.10187 | AH7: 107.40202 | AI7: 111.70218 | AJ7: 116.00233 | AK7: 120.3025 | AL7: 124.60265 | AM7: 128.90281 | AN7: 133.20296 | AO7: 137.50312 | AP7: 141.80327 | AQ7: 146.10343 | AR7: 150.40358 | AS7: 154.70374 | AT7: 159.00389 | AU7: 163.30405 | AV7: 167.6042 | AW7: 171.90436 | AX7: 176.20451 | AY7: 180.50467 | AZ7: 0 | BA7: 0 | BB7: 0 | BC7: 0 | BD7: 0 | BE7: 0 | BF7: 0 | BG7: 0 | BH7: 0 | BI7: 0 | BJ7: 0 | BK7: 0 | BL7: 0 | BM7: 0 | BN7: 0 | BO7: 0 | BP7: 0 | BQ7: 0 | BR7: 0 | BS7: 0 | BT7: 0 | BU7: 0 | BV7: 0 | BW7: 0 | BX7: 0 | BY7: 0 | BZ7: 0 | CA7: 0 | CB7: 0 | CC7: 0 | CD7: 0 | CE7: 0 | CF7: 0 | CG7: 0 | CH7: 0 | CI7: 0 | CJ7: 0 | CK7: 0 | CL7: 0 | CM7: 0 | CN7: 0 | CO7: 0 | CP7: 0 | CQ7: 0 | CR7: 0 | CS7: 0 | CT7: 0 | CU7: 0 | CV7: 0 | CW7: 0
A8: IE | B8: 0 | C8: 0 | D8: 0 | E8: 0 | F8: 0 | G8: 0 | H8: 0 | I8: 0 | J8: 0 | K8: 17.911437 | L8: 24.644988 | M8: 9.6709922 | N8: 6.2699024 | O8: 7.0097019 | P8: 7.9772951 | Q8: 6.1431508 | R8: 5.8558704 | S8: 16.87171 | T8: 25.421822 | U8: 19.229474 | V8: 51.640468 | W8: 89.760731 | X8: 99.89806 | Y8: 63.593197 | Z8: 73.000779 | AA8: 77.300934 | AB8: 81.60109 | AC8: 85.901246 | AD8: 90.201402 | AE8: 94.501558 | AF8: 98.801713 | AG8: 103.10187 | AH8: 107.40202 | AI8: 111.70218 | AJ8: 116.00233 | AK8: 120.3025 | AL8: 124.60265 | AM8: 128.90281 | AN8: 133.20296 | AO8: 137.50312 | AP8: 141.80327 | AQ8: 146.10343 | AR8: 150.40358 | AS8: 154.70374 | AT8: 159.00389 | AU8: 163.30405 | AV8: 167.6042 | AW8: 171.90436 | AX8: 176.20451 | AY8: 180.50467 | AZ8: 0 | BA8: 0 | BB8: 0 | BC8: 0 | BD8: 0 | BE8: 0 | BF8: 0 | BG8: 0 | BH8: 0 | BI8: 0 | BJ8: 0 | BK8: 0 | BL8: 0 | BM8: 0 | BN8: 0 | BO8: 0 | BP8: 0 | BQ8: 0 | BR8: 0 | BS8: 0 | BT8: 0 | BU8: 0 | BV8: 0 | BW8: 0 | BX8: 0 | BY8: 0 | BZ8: 0 | CA8: 0 | CB8: 0 | CC8: 0 | CD8: 0 | CE8: 0 | CF8: 0 | CG8: 0 | CH8: 0 | CI8: 0 | CJ8: 0 | CK8: 0 | CL8: 0 | CM8: 0 | CN8: 0 | CO8: 0 | CP8: 0 | CQ8: 0 | CR8: 0 | CS8: 0 | CT8: 0 | CU8: 0 | CV8: 0 | CW8: 0
A9: IT | B9: 0 | C9: 0 | D9: 0 | E9: 0 | F9: 0 | G9: 0 | H9: 0 | I9: 0 | J9: 0 | K9: 17.911437 | L9: 24.644988 | M9: 9.6709922 | N9: 6.2699024 | O9: 7.0097019 | P9: 7.9772951 | Q9: 6.1431508 | R9: 5.8558704 | S9: 16.87171 | T9: 25.421822 | U9: 19.229474 | V9: 51.640468 | W9: 89.760731 | X9: 99.89806 | Y9: 63.593197 | Z9: 73.000779 | AA9: 77.300934 | AB9: 81.60109 | AC9: 85.901246 | AD9: 90.201402 | AE9: 94.501558 | AF9: 98.801713 | AG9: 103.10187 | AH9: 107.40202 | AI9: 111.70218 | AJ9: 116.00233 | AK9: 120.3025 | AL9: 124.60265 | AM9: 128.90281 | AN9: 133.20296 | AO9: 137.50312 | AP9: 141.80327 | AQ9: 146.10343 | AR9: 150.40358 | AS9: 154.70374 | AT9: 159.00389 | AU9: 163.30405 | AV9: 167.6042 | AW9: 171.90436 | AX9: 176.20451 | AY9: 180.50467 | AZ9: 0 | BA9: 0 | BB9: 0 | BC9: 0 | BD9: 0 | BE9: 0 | BF9: 0 | BG9: 0 | BH9: 0 | BI9: 0 | BJ9: 0 | BK9: 0 | BL9: 0 | BM9: 0 | BN9: 0 | BO9: 0 | BP9: 0 | BQ9: 0 | BR9: 0 | BS9: 0 | BT9: 0 | BU9: 0 | BV9: 0 | BW9: 0 | BX9: 0 | BY9: 0 | BZ9: 0 | CA9: 0 | CB9: 0 | CC9: 0 | CD9: 0 | CE9: 0 | CF9: 0 | CG9: 0 | CH9: 0 | CI9: 0 | CJ9: 0 | CK9: 0 | CL9: 0 | CM9: 0 | CN9: 0 | CO9: 0 | CP9: 0 | CQ9: 0 | CR9: 0 | CS9: 0 | CT9: 0 | CU9: 0 | CV9: 0 | CW9: 0
A10: LX | B10: 0 | C10: 0 | D10: 0 | E10: 0 | F10: 0 | G10: 0 | H10: 0 | I10: 0 | J10: 0 | K10: 17.911437 | L10: 24.644988 | M10: 9.6709922 | N10: 6.2699024 | O10: 7.0097019 | P10: 7.9772951 | Q10: 6.1431508 | R10: 5.8558704 | S10: 16.87171 | T10: 25.421822 | U10: 19.229474 | V10: 51.640468 | W10: 89.760731 | X10: 99.89806 | Y10: 63.593197 | Z10: 73.000779 | AA10: 77.300934 | AB10: 81.60109 | AC10: 85.901246 | AD10: 90.201402 | AE10: 94.501558 | AF10: 98.801713 | AG10: 103.10187 | AH10: 107.40202 | AI10: 111.70218 | AJ10: 116.00233 | AK10: 120.3025 | AL10: 124.60265 | AM10: 128.90281 | AN10: 133.20296 | AO10: 137.50312 | AP10: 141.80327 | AQ10: 146.10343 | AR10: 150.40358 | AS10: 154.70374 | AT10: 159.00389 | AU10: 163.30405 | AV10: 167.6042 | AW10: 171.90436 | AX10: 176.20451 | AY10: 180.50467 | AZ10: 0 | BA10: 0 | BB10: 0 | BC10: 0 | BD10: 0 | BE10: 0 | BF10: 0 | BG10: 0 | BH10: 0 | BI10: 0 | BJ10: 0 | BK10: 0 | BL10: 0 | BM10: 0 | BN10: 0 | BO10: 0 | BP10: 0 | BQ10: 0 | BR10: 0 | BS10: 0 | BT10: 0 | BU10: 0 | BV10: 0 | BW10: 0 | BX10: 0 | BY10: 0 | BZ10: 0 | CA10: 0 | CB10: 0 | CC10: 0 | CD10: 0 | CE10: 0 | CF10: 0 | CG10: 0 | CH10: 0 | CI10: 0 | CJ10: 0 | CK10: 0 | CL10: 0 | CM10: 0 | CN10: 0 | CO10: 0 | CP10: 0 | CQ10: 0 | CR10: 0 | CS10: 0 | CT10: 0 | CU10: 0 | CV10: 0 | CW10: 0
A11: NL | B11: 0 | C11: 0 | D11: 0 | E11: 0 | F11: 0 | G11: 0 | H11: 0 | I11: 0 | J11: 0 | K11: 17.911437 | L11: 24.644988 | M11: 9.6709922 | N11: 6.2699024 | O11: 7.0097019 | P11: 7.9772951 | Q11: 6.1431508 | R11: 5.8558704 | S11: 16.87171 | T11: 25.421822 | U11: 19.229474 | V11: 51.640468 | W11: 89.760731 | X11: 99.89806 | Y11: 63.593197 | Z11: 73.000779 | AA11: 77.300934 | AB11: 81.60109 | AC11: 85.901246 | AD11: 90.201402 | AE11: 94.501558 | AF11: 98.801713 | AG11: 103.10187 | AH11: 107.40202 | AI11: 111.70218 | AJ11: 116.00233 | AK11: 120.3025 | AL11: 124.60265 | AM11: 128.90281 | AN11: 133.20296 | AO11: 137.50312 | AP11: 141.80327 | AQ11: 146.10343 | AR11: 150.40358 | AS11: 154.70374 | AT11: 159.00389 | AU11: 163.30405 | AV11: 167.6042 | AW11: 171.90436 | AX11: 176.20451 | AY11: 180.50467 | AZ11: 0 | BA11: 0 | BB11: 0 | BC11: 0 | BD11: 0 | BE11: 0 | BF11: 0 | BG11: 0 | BH11: 0 | BI11: 0 | BJ11: 0 | BK11: 0 | BL11: 0 | BM11: 0 | BN11: 0 | BO11: 0 | BP11: 0 | BQ11: 0 | BR11: 0 | BS11: 0 | BT11: 0 | BU11: 0 | BV11: 0 | BW11: 0 | BX11: 0 | BY11: 0 | BZ11: 0 | CA11: 0 | CB11: 0 | CC11: 0 | CD11: 0 | CE11: 0 | CF11: 0 | CG11: 0 | CH11: 0 | CI11: 0 | CJ11: 0 | CK11: 0 | CL11: 0 | CM11: 0 | CN11: 0 | CO11: 0 | CP11: 0 | CQ11: 0 | CR11: 0 | CS11: 0 | CT11: 0 | CU11: 0 | CV11: 0 | CW11: 0
A12: AT | B12: 0 | C12: 0 | D12: 0 | E12: 0 | F12: 0 | G12: 0 | H12: 0 | I12: 0 | J12: 0 | K12: 17.911437 | L12: 24.644988 | M12: 9.6709922 | N12: 6.2699024 | O12: 7.0097019 | P12: 7.9772951 | Q12: 6.1431508 | R12: 5.8558704 | S12: 16.87171 | T12: 25.421822 | U12: 19.229474 | V12: 51.640468 | W12: 89.760731 | X12: 99.89806 | Y12: 63.593197 | Z12: 73.000779 | AA12: 77.300934 | AB12: 81.60109 | AC12: 85.901246 | AD12: 90.201402 | AE12: 94.501558 | AF12: 98.801713 | AG12: 103.10187 | AH12: 107.40202 | AI12: 111.70218 | AJ12: 116.00233 | AK12: 120.3025 | AL12: 124.60265 | AM12: 128.90281 | AN12: 133.20296 | AO12: 137.50312 | AP12: 141.80327 | AQ12: 146.10343 | AR12: 150.40358 | AS12: 154.70374 | AT12: 159.00389 | AU12: 163.30405 | AV12: 167.6042 | AW12: 171.90436 | AX12: 176.20451 | AY12: 180.50467 | AZ12: 0 | BA12: 0 | BB12: 0 | BC12: 0 | BD12: 0 | BE12: 0 | BF12: 0 | BG12: 0 | BH12: 0 | BI12: 0 | BJ12: 0 | BK12: 0 | BL12: 0 | BM12: 0 | BN12: 0 | BO12: 0 | BP12: 0 | BQ12: 0 | BR12: 0 | BS12: 0 | BT12: 0 | BU12: 0 | BV12: 0 | BW12: 0 | BX12: 0 | BY12: 0 | BZ12: 0 | CA12: 0 | CB12: 0 | CC12: 0 | CD12: 0 | CE12: 0 | CF12: 0 | CG12: 0 | CH12: 0 | CI12: 0 | CJ12: 0 | CK12: 0 | CL12: 0 | CM12: 0 | CN12: 0 | CO12: 0 | CP12: 0 | CQ12: 0 | CR12: 0 | CS12: 0 | CT12: 0 | CU12: 0 | CV12: 0 | CW12: 0
A13: PT | B13: 0 | C13: 0 | D13: 0 | E13: 0 | F13: 0 | G13: 0 | H13: 0 | I13: 0 | J13: 0 | K13: 17.911437 | L13: 24.644988 | M13: 9.6709922 | N13: 6.2699024 | O13: 7.0097019 | P13: 7.9772951 | Q13: 6.1431508 | R13: 5.8558704 | S13: 16.87171 | T13: 25.421822 | U13: 19.229474 | V13: 51.640468 | W13: 89.760731 | X13: 99.89806 | Y13: 63.593197 | Z13: 73.000779 | AA13: 77.300934 | AB13: 81.60109 | AC13: 85.901246 | AD13: 90.201402 | AE13: 94.501558 | AF13: 98.801713 | AG13: 103.10187 | AH13: 107.40202 | AI13: 111.70218 | AJ13: 116.00233 | AK13: 120.3025 | AL13: 124.60265 | AM13: 128.90281 | AN13: 133.20296 | AO13: 137.50312 | AP13: 141.80327 | AQ13: 146.10343 | AR13: 150.40358 | AS13: 154.70374 | AT13: 159.00389 | AU13: 163.30405 | AV13: 167.6042 | AW13: 171.90436 | AX13: 176.20451 | AY13: 180.50467 | AZ13: 0 | BA13: 0 | BB13: 0 | BC13: 0 | BD13: 0 | BE13: 0 | BF13: 0 | BG13: 0 | BH13: 0 | BI13: 0 | BJ13: 0 | BK13: 0 | BL13: 0 | BM13: 0 | BN13: 0 | BO13: 0 | BP13: 0 | BQ13: 0 | BR13: 0 | BS13: 0 | BT13: 0 | BU13: 0 | BV13: 0 | BW13: 0 | BX13: 0 | BY13: 0 | BZ13: 0 | CA13: 0 | CB13: 0 | CC13: 0 | CD13: 0 | CE13: 0 | CF13: 0 | CG13: 0 | CH13: 0 | CI13: 0 | CJ13: 0 | CK13: 0 | CL13: 0 | CM13: 0 | CN13: 0 | CO13: 0 | CP13: 0 | CQ13: 0 | CR13: 0 | CS13: 0 | CT13: 0 | CU13: 0 | CV13: 0 | CW13: 0
... A72: PK | B72: 0 | C72: 0 | D72: 0 | E72: 0 | F72: 0 | G72: 0 | H72: 0 | I72: 0 | J72: 0 | K72: 0 | L72: 0 | M72: 0 | N72: 0 | O72: 0 | P72: 0 | Q72: 0 | R72: 0 | S72: 0 | T72: 0 | U72: 0 | V72: 0 | W72: 0 | X72: 0 | Y72: 0 | Z72: 0 | AA72: 0 | AB72: 0 | AC72: 0 | AD72: 0 | AE72: 0 | AF72: 0 | AG72: 0 | AH72: 0 | AI72: 0 | AJ72: 0 | AK72: 0 | AL72: 0 | AM72: 0 | AN72: 0 | AO72: 0 | AP72: 0 | AQ72: 0 | AR72: 0 | AS72: 0 | AT72: 0 | AU72: 0 | AV72: 0 | AW72: 0 | AX72: 0 | AY72: 0 | AZ72: 0 | BA72: 0 | BB72: 0 | BC72: 0 | BD72: 0 | BE72: 0 | BF72: 0 | BG72: 0 | BH72: 0 | BI72: 0 | BJ72: 0 | BK72: 0 | BL72: 0 | BM72: 0 | BN72: 0 | BO72: 0 | BP72: 0 | BQ72: 0 | BR72: 0 | BS72: 0 | BT72: 0 | BU72: 0 | BV72: 0 | BW72: 0 | BX72: 0 | BY72: 0 | BZ72: 0 | CA72: 0 | CB72: 0 | CC72: 0 | CD72: 0 | CE72: 0 | CF72: 0 | CG72: 0 | CH72: 0 | CI72: 0 | CJ72: 0 | CK72: 0 | CL72: 0 | CM72: 0 | CN72: 0 | CO72: 0 | CP72: 0 | CQ72: 0 | CR72: 0 | CS72: 0 | CT72: 0 | CU72: 0 | CV72: 0 | CW72: 0

Sheet HYPR-S1
B1: 2001 | C1: 2002 | D1: 2003 | E1: 2004 | F1: 2005 | G1: 2006 | H1: 2007 | I1: 2008 | J1: 2009 | K1: 2010 | L1: 2011 | M1: 2012 | N1: 2013 | O1: 2014 | P1: 2015 | Q1: 2016 | R1: 2017 | S1: 2018 | T1: 2019 | U1: 2020 | V1: 2021 | W1: 2022 | X1: 2023 | Y1: 2024 | Z1: 2025 | AA1: 2026 | AB1: 2027 | AC1: 2028 | AD1: 2029 | AE1: 2030 | AF1: 2031 | AG1: 2032 | AH1: 2033 | AI1: 2034 | AJ1: 2035 | AK1: 2036 | AL1: 2037 | AM1: 2038 | AN1: 2039 | AO1: 2040 | AP1: 2041 | AQ1: 2042 | AR1: 2043 | AS1: 2044 | AT1: 2045 | AU1: 2046 | AV1: 2047 | AW1: 2048 | AX1: 2049 | AY1: 2050 | AZ1: 2051 | BA1: 2052 | BB1: 2053 | BC1: 2054 | BD1: 2055 | BE1: 2056 | BF1: 2057 | BG1: 2058 | BH1: 2059 | BI1: 2060 | BJ1: 2061 | BK1: 2062 | BL1: 2063 | BM1: 2064 | BN1: 2065 | BO1: 2066 | BP1: 2067 | BQ1: 2068 | BR1: 2069 | BS1: 2070 | BT1: 2071 | BU1: 2072 | BV1: 2073 | BW1: 2074 | BX1: 2075 | BY1: 2076 | BZ1: 2077 | CA1: 2078 | CB1: 2079 | CC1: 2080 | CD1: 2081 | CE1: 2082 | CF1: 2083 | CG1: 2084 | CH1: 2085 | CI1: 2086 | CJ1: 2087 | CK1: 2088 | CL1: 2089 | CM1: 2090 | CN1: 2091 | CO1: 2092 | CP1: 2093 | CQ1: 2094 | CR1: 2095 | CS1: 2096 | CT1: 2097 | CU1: 2098 | CV1: 2099 | CW1: 2100
A2: BE | B2: 0 | C2: 0 | D2: 0 | E2: 0 | F2: 0 | G2: 0 | H2: 0 | I2: 0 | J2: 0 | K2: =MAX('HYPR-S0'!K2,'HYPR-S1'!K$75) -> 17.911437 | L2: =MAX('HYPR-S0'!L2,'HYPR-S1'!L$75) -> 24.644988 | M2: =MAX('HYPR-S0'!M2,'HYPR-S1'!M$75) -> 9.6709922 | N2: =MAX('HYPR-S0'!N2,'HYPR-S1'!N$75) -> 6.2699024 | O2: =MAX('HYPR-S0'!O2,'HYPR-S1'!O$75) -> 7.0097019 | P2: =MAX('HYPR-S0'!P2,'HYPR-S1'!P$75) -> 7.9772951 | Q2: =MAX('HYPR-S0'!Q2,'HYPR-S1'!Q$75) -> 6.1431508 | R2: =MAX('HYPR-S0'!R2,'HYPR-S1'!R$75) -> 5.8558704 | ... AY2: =MAX('HYPR-S0'!AY2,'HYPR-S1'!AY$75) -> 193.84615 | AZ2: 0 | BA2: 0 | BB2: 0 | BC2: 0 | BD2: 0 | BE2: 0 | BF2: 0 | BG2: 0 | BH2: 0 | BI2: 0 | BJ2: 0 | BK2: 0 | BL2: 0 | BM2: 0 | BN2: 0 | BO2: 0 | BP2: 0 | BQ2: 0 | BR2: 0 | BS2: 0 | BT2: 0 | BU2: 0 | BV2: 0 | BW2: 0 | BX2: 0 | BY2: 0 | BZ2: 0 | CA2: 0 | CB2: 0 | CC2: 0 | CD2: 0 | CE2: 0 | CF2: 0 | CG2: 0 | CH2: 0 | CI2: 0 | CJ2: 0 | CK2: 0 | CL2: 0 | CM2: 0 | CN2: 0 | CO2: 0 | CP2: 0 | CQ2: 0 | CR2: 0 | CS2: 0 | CT2: 0 | CU2: 0 | CV2: 0 | CW2: 0
A3: DK | B3: 0 | C3: 0 | D3: 0 | E3: 0 | F3: 0 | G3: 0 | H3: 0 | I3: 0 | J3: 0 | K3: =MAX('HYPR-S0'!K3,'HYPR-S1'!K$75) -> 17.911437 | L3: =MAX('HYPR-S0'!L3,'HYPR-S1'!L$75) -> 24.644988 | M3: =MAX('HYPR-S0'!M3,'HYPR-S1'!M$75) -> 9.6709922 | N3: =MAX('HYPR-S0'!N3,'HYPR-S1'!N$75) -> 6.2699024 | O3: =MAX('HYPR-S0'!O3,'HYPR-S1'!O$75) -> 7.0097019 | P3: =MAX('HYPR-S0'!P3,'HYPR-S1'!P$75) -> 7.9772951 | Q3: =MAX('HYPR-S0'!Q3,'HYPR-S1'!Q$75) -> 6.1431508 | R3: =MAX('HYPR-S0'!R3,'HYPR-S1'!R$75) -> 5.8558704 | ... AY3: =MAX('HYPR-S0'!AY3,'HYPR-S1'!AY$75) -> 193.84615 | AZ3: 0 | BA3: 0 | BB3: 0 | BC3: 0 | BD3: 0 | BE3: 0 | BF3: 0 | BG3: 0 | BH3: 0 | BI3: 0 | BJ3: 0 | BK3: 0 | BL3: 0 | BM3: 0 | BN3: 0 | BO3: 0 | BP3: 0 | BQ3: 0 | BR3: 0 | BS3: 0 | BT3: 0 | BU3: 0 | BV3: 0 | BW3: 0 | BX3: 0 | BY3: 0 | BZ3: 0 | CA3: 0 | CB3: 0 | CC3: 0 | CD3: 0 | CE3: 0 | CF3: 0 | CG3: 0 | CH3: 0 | CI3: 0 | CJ3: 0 | CK3: 0 | CL3: 0 | CM3: 0 | CN3: 0 | CO3: 0 | CP3: 0 | CQ3: 0 | CR3: 0 | CS3: 0 | CT3: 0 | CU3: 0 | CV3: 0 | CW3: 0
A4: DE | B4: 0 | C4: 0 | D4: 0 | E4: 0 | F4: 0 | G4: 0 | H4: 0 | I4: 0 | J4: 0 | K4: =MAX('HYPR-S0'!K4,'HYPR-S1'!K$75) -> 17.911437 | L4: =MAX('HYPR-S0'!L4,'HYPR-S1'!L$75) -> 24.644988 | M4: =MAX('HYPR-S0'!M4,'HYPR-S1'!M$75) -> 9.6709922 | N4: =MAX('HYPR-S0'!N4,'HYPR-S1'!N$75) -> 6.2699024 | O4: =MAX('HYPR-S0'!O4,'HYPR-S1'!O$75) -> 7.0097019 | P4: =MAX('HYPR-S0'!P4,'HYPR-S1'!P$75) -> 7.9772951 | Q4: =MAX('HYPR-S0'!Q4,'HYPR-S1'!Q$75) -> 6.1431508 | R4: =MAX('HYPR-S0'!R4,'HYPR-S1'!R$75) -> 5.8558704 | ... AY4: =MAX('HYPR-S0'!AY4,'HYPR-S1'!AY$75) -> 193.84615 | AZ4: 0 | BA4: 0 | BB4: 0 | BC4: 0 | BD4: 0 | BE4: 0 | BF4: 0 | BG4: 0 | BH4: 0 | BI4: 0 | BJ4: 0 | BK4: 0 | BL4: 0 | BM4: 0 | BN4: 0 | BO4: 0 | BP4: 0 | BQ4: 0 | BR4: 0 | BS4: 0 | BT4: 0 | BU4: 0 | BV4: 0 | BW4: 0 | BX4: 0 | BY4: 0 | BZ4: 0 | CA4: 0 | CB4: 0 | CC4: 0 | CD4: 0 | CE4: 0 | CF4: 0 | CG4: 0 | CH4: 0 | CI4: 0 | CJ4: 0 | CK4: 0 | CL4: 0 | CM4: 0 | CN4: 0 | CO4: 0 | CP4: 0 | CQ4: 0 | CR4: 0 | CS4: 0 | CT4: 0 | CU4: 0 | CV4: 0 | CW4: 0
A5: EL | B5: 0 | C5: 0 | D5: 0 | E5: 0 | F5: 0 | G5: 0 | H5: 0 | I5: 0 | J5: 0 | K5: =MAX('HYPR-S0'!K5,'HYPR-S1'!K$75) -> 17.911437 | L5: =MAX('HYPR-S0'!L5,'HYPR-S1'!L$75) -> 24.644988 | M5: =MAX('HYPR-S0'!M5,'HYPR-S1'!M$75) -> 9.6709922 | N5: =MAX('HYPR-S0'!N5,'HYPR-S1'!N$75) -> 6.2699024 | O5: =MAX('HYPR-S0'!O5,'HYPR-S1'!O$75) -> 7.0097019 | P5: =MAX('HYPR-S0'!P5,'HYPR-S1'!P$75) -> 7.9772951 | Q5: =MAX('HYPR-S0'!Q5,'HYPR-S1'!Q$75) -> 6.1431508 | R5: =MAX('HYPR-S0'!R5,'HYPR-S1'!R$75) -> 5.8558704 | ... AY5: =MAX('HYPR-S0'!AY5,'HYPR-S1'!AY$75) -> 193.84615 | AZ5: 0 | BA5: 0 | BB5: 0 | BC5: 0 | BD5: 0 | BE5: 0 | BF5: 0 | BG5: 0 | BH5: 0 | BI5: 0 | BJ5: 0 | BK5: 0 | BL5: 0 | BM5: 0 | BN5: 0 | BO5: 0 | BP5: 0 | BQ5: 0 | BR5: 0 | BS5: 0 | BT5: 0 | BU5: 0 | BV5: 0 | BW5: 0 | BX5: 0 | BY5: 0 | BZ5: 0 | CA5: 0 | CB5: 0 | CC5: 0 | CD5: 0 | CE5: 0 | CF5: 0 | CG5: 0 | CH5: 0 | CI5: 0 | CJ5: 0 | CK5: 0 | CL5: 0 | CM5: 0 | CN5: 0 | CO5: 0 | CP5: 0 | CQ5: 0 | CR5: 0 | CS5: 0 | CT5: 0 | CU5: 0 | CV5: 0 | CW5: 0
A6: ES | B6: 0 | C6: 0 | D6: 0 | E6: 0 | F6: 0 | G6: 0 | H6: 0 | I6: 0 | J6: 0 | K6: =MAX('HYPR-S0'!K6,'HYPR-S1'!K$75) -> 17.911437 | L6: =MAX('HYPR-S0'!L6,'HYPR-S1'!L$75) -> 24.644988 | M6: =MAX('HYPR-S0'!M6,'HYPR-S1'!M$75) -> 9.6709922 | N6: =MAX('HYPR-S0'!N6,'HYPR-S1'!N$75) -> 6.2699024 | O6: =MAX('HYPR-S0'!O6,'HYPR-S1'!O$75) -> 7.0097019 | P6: =MAX('HYPR-S0'!P6,'HYPR-S1'!P$75) -> 7.9772951 | Q6: =MAX('HYPR-S0'!Q6,'HYPR-S1'!Q$75) -> 6.1431508 | R6: =MAX('HYPR-S0'!R6,'HYPR-S1'!R$75) -> 5.8558704 | ... AY6: =MAX('HYPR-S0'!AY6,'HYPR-S1'!AY$75) -> 193.84615 | AZ6: 0 | BA6: 0 | BB6: 0 | BC6: 0 | BD6: 0 | BE6: 0 | BF6: 0 | BG6: 0 | BH6: 0 | BI6: 0 | BJ6: 0 | BK6: 0 | BL6: 0 | BM6: 0 | BN6: 0 | BO6: 0 | BP6: 0 | BQ6: 0 | BR6: 0 | BS6: 0 | BT6: 0 | BU6: 0 | BV6: 0 | BW6: 0 | BX6: 0 | BY6: 0 | BZ6: 0 | CA6: 0 | CB6: 0 | CC6: 0 | CD6: 0 | CE6: 0 | CF6: 0 | CG6: 0 | CH6: 0 | CI6: 0 | CJ6: 0 | CK6: 0 | CL6: 0 | CM6: 0 | CN6: 0 | CO6: 0 | CP6: 0 | CQ6: 0 | CR6: 0 | CS6: 0 | CT6: 0 | CU6: 0 | CV6: 0 | CW6: 0
A7: FR | B7: 0 | C7: 0 | D7: 0 | E7: 0 | F7: 0 | G7: 0 | H7: 0 | I7: 0 | J7: 0 | K7: =MAX('HYPR-S0'!K7,'HYPR-S1'!K$75) -> 17.911437 | L7: =MAX('HYPR-S0'!L7,'HYPR-S1'!L$75) -> 24.644988 | M7: =MAX('HYPR-S0'!M7,'HYPR-S1'!M$75) -> 9.6709922 | N7: =MAX('HYPR-S0'!N7,'HYPR-S1'!N$75) -> 6.2699024 | O7: =MAX('HYPR-S0'!O7,'HYPR-S1'!O$75) -> 7.0097019 | P7: =MAX('HYPR-S0'!P7,'HYPR-S1'!P$75) -> 7.9772951 | Q7: =MAX('HYPR-S0'!Q7,'HYPR-S1'!Q$75) -> 6.1431508 | R7: =MAX('HYPR-S0'!R7,'HYPR-S1'!R$75) -> 5.8558704 | ... AY7: =MAX('HYPR-S0'!AY7,'HYPR-S1'!AY$75) -> 193.84615 | AZ7: 0 | BA7: 0 | BB7: 0 | BC7: 0 | BD7: 0 | BE7: 0 | BF7: 0 | BG7: 0 | BH7: 0 | BI7: 0 | BJ7: 0 | BK7: 0 | BL7: 0 | BM7: 0 | BN7: 0 | BO7: 0 | BP7: 0 | BQ7: 0 | BR7: 0 | BS7: 0 | BT7: 0 | BU7: 0 | BV7: 0 | BW7: 0 | BX7: 0 | BY7: 0 | BZ7: 0 | CA7: 0 | CB7: 0 | CC7: 0 | CD7: 0 | CE7: 0 | CF7: 0 | CG7: 0 | CH7: 0 | CI7: 0 | CJ7: 0 | CK7: 0 | CL7: 0 | CM7: 0 | CN7: 0 | CO7: 0 | CP7: 0 | CQ7: 0 | CR7: 0 | CS7: 0 | CT7: 0 | CU7: 0 | CV7: 0 | CW7: 0
A8: IE | B8: 0 | C8: 0 | D8: 0 | E8: 0 | F8: 0 | G8: 0 | H8: 0 | I8: 0 | J8: 0 | K8: =MAX('HYPR-S0'!K8,'HYPR-S1'!K$75) -> 17.911437 | L8: =MAX('HYPR-S0'!L8,'HYPR-S1'!L$75) -> 24.644988 | M8: =MAX('HYPR-S0'!M8,'HYPR-S1'!M$75) -> 9.6709922 | N8: =MAX('HYPR-S0'!N8,'HYPR-S1'!N$75) -> 6.2699024 | O8: =MAX('HYPR-S0'!O8,'HYPR-S1'!O$75) -> 7.0097019 | P8: =MAX('HYPR-S0'!P8,'HYPR-S1'!P$75) -> 7.9772951 | Q8: =MAX('HYPR-S0'!Q8,'HYPR-S1'!Q$75) -> 6.1431508 | R8: =MAX('HYPR-S0'!R8,'HYPR-S1'!R$75) -> 5.8558704 | ... AY8: =MAX('HYPR-S0'!AY8,'HYPR-S1'!AY$75) -> 193.84615 | AZ8: 0 | BA8: 0 | BB8: 0 | BC8: 0 | BD8: 0 | BE8: 0 | BF8: 0 | BG8: 0 | BH8: 0 | BI8: 0 | BJ8: 0 | BK8: 0 | BL8: 0 | BM8: 0 | BN8: 0 | BO8: 0 | BP8: 0 | BQ8: 0 | BR8: 0 | BS8: 0 | BT8: 0 | BU8: 0 | BV8: 0 | BW8: 0 | BX8: 0 | BY8: 0 | BZ8: 0 | CA8: 0 | CB8: 0 | CC8: 0 | CD8: 0 | CE8: 0 | CF8: 0 | CG8: 0 | CH8: 0 | CI8: 0 | CJ8: 0 | CK8: 0 | CL8: 0 | CM8: 0 | CN8: 0 | CO8: 0 | CP8: 0 | CQ8: 0 | CR8: 0 | CS8: 0 | CT8: 0 | CU8: 0 | CV8: 0 | CW8: 0
A9: IT | B9: 0 | C9: 0 | D9: 0 | E9: 0 | F9: 0 | G9: 0 | H9: 0 | I9: 0 | J9: 0 | K9: =MAX('HYPR-S0'!K9,'HYPR-S1'!K$75) -> 17.911437 | L9: =MAX('HYPR-S0'!L9,'HYPR-S1'!L$75) -> 24.644988 | M9: =MAX('HYPR-S0'!M9,'HYPR-S1'!M$75) -> 9.6709922 | N9: =MAX('HYPR-S0'!N9,'HYPR-S1'!N$75) -> 6.2699024 | O9: =MAX('HYPR-S0'!O9,'HYPR-S1'!O$75) -> 7.0097019 | P9: =MAX('HYPR-S0'!P9,'HYPR-S1'!P$75) -> 7.9772951 | Q9: =MAX('HYPR-S0'!Q9,'HYPR-S1'!Q$75) -> 6.1431508 | R9: =MAX('HYPR-S0'!R9,'HYPR-S1'!R$75) -> 5.8558704 | ... AY9: =MAX('HYPR-S0'!AY9,'HYPR-S1'!AY$75) -> 193.84615 | AZ9: 0 | BA9: 0 | BB9: 0 | BC9: 0 | BD9: 0 | BE9: 0 | BF9: 0 | BG9: 0 | BH9: 0 | BI9: 0 | BJ9: 0 | BK9: 0 | BL9: 0 | BM9: 0 | BN9: 0 | BO9: 0 | BP9: 0 | BQ9: 0 | BR9: 0 | BS9: 0 | BT9: 0 | BU9: 0 | BV9: 0 | BW9: 0 | BX9: 0 | BY9: 0 | BZ9: 0 | CA9: 0 | CB9: 0 | CC9: 0 | CD9: 0 | CE9: 0 | CF9: 0 | CG9: 0 | CH9: 0 | CI9: 0 | CJ9: 0 | CK9: 0 | CL9: 0 | CM9: 0 | CN9: 0 | CO9: 0 | CP9: 0 | CQ9: 0 | CR9: 0 | CS9: 0 | CT9: 0 | CU9: 0 | CV9: 0 | CW9: 0
A10: LX | B10: 0 | C10: 0 | D10: 0 | E10: 0 | F10: 0 | G10: 0 | H10: 0 | I10: 0 | J10: 0 | K10: =MAX('HYPR-S0'!K10,'HYPR-S1'!K$75) -> 17.911437 | L10: =MAX('HYPR-S0'!L10,'HYPR-S1'!L$75) -> 24.644988 | M10: =MAX('HYPR-S0'!M10,'HYPR-S1'!M$75) -> 9.6709922 | N10: =MAX('HYPR-S0'!N10,'HYPR-S1'!N$75) -> 6.2699024 | O10: =MAX('HYPR-S0'!O10,'HYPR-S1'!O$75) -> 7.0097019 | P10: =MAX('HYPR-S0'!P10,'HYPR-S1'!P$75) -> 7.9772951 | Q10: =MAX('HYPR-S0'!Q10,'HYPR-S1'!Q$75) -> 6.1431508 | R10: =MAX('HYPR-S0'!R10,'HYPR-S1'!R$75) -> 5.8558704 | ... AY10: =MAX('HYPR-S0'!AY10,'HYPR-S1'!AY$75) -> 193.84615 | AZ10: 0 | BA10: 0 | BB10: 0 | BC10: 0 | BD10: 0 | BE10: 0 | BF10: 0 | BG10: 0 | BH10: 0 | BI10: 0 | BJ10: 0 | BK10: 0 | BL10: 0 | BM10: 0 | BN10: 0 | BO10: 0 | BP10: 0 | BQ10: 0 | BR10: 0 | BS10: 0 | BT10: 0 | BU10: 0 | BV10: 0 | BW10: 0 | BX10: 0 | BY10: 0 | BZ10: 0 | CA10: 0 | CB10: 0 | CC10: 0 | CD10: 0 | CE10: 0 | CF10: 0 | CG10: 0 | CH10: 0 | CI10: 0 | CJ10: 0 | CK10: 0 | CL10: 0 | CM10: 0 | CN10: 0 | CO10: 0 | CP10: 0 | CQ10: 0 | CR10: 0 | CS10: 0 | CT10: 0 | CU10: 0 | CV10: 0 | CW10: 0
A11: NL | B11: 0 | C11: 0 | D11: 0 | E11: 0 | F11: 0 | G11: 0 | H11: 0 | I11: 0 | J11: 0 | K11: =MAX('HYPR-S0'!K11,'HYPR-S1'!K$75) -> 17.911437 | L11: =MAX('HYPR-S0'!L11,'HYPR-S1'!L$75) -> 24.644988 | M11: =MAX('HYPR-S0'!M11,'HYPR-S1'!M$75) -> 9.6709922 | N11: =MAX('HYPR-S0'!N11,'HYPR-S1'!N$75) -> 6.2699024 | O11: =MAX('HYPR-S0'!O11,'HYPR-S1'!O$75) -> 7.0097019 | P11: =MAX('HYPR-S0'!P11,'HYPR-S1'!P$75) -> 7.9772951 | Q11: =MAX('HYPR-S0'!Q11,'HYPR-S1'!Q$75) -> 6.1431508 | R11: =MAX('HYPR-S0'!R11,'HYPR-S1'!R$75) -> 5.8558704 | ... AY11: =MAX('HYPR-S0'!AY11,'HYPR-S1'!AY$75) -> 193.84615 | AZ11: 0 | BA11: 0 | BB11: 0 | BC11: 0 | BD11: 0 | BE11: 0 | BF11: 0 | BG11: 0 | BH11: 0 | BI11: 0 | BJ11: 0 | BK11: 0 | BL11: 0 | BM11: 0 | BN11: 0 | BO11: 0 | BP11: 0 | BQ11: 0 | BR11: 0 | BS11: 0 | BT11: 0 | BU11: 0 | BV11: 0 | BW11: 0 | BX11: 0 | BY11: 0 | BZ11: 0 | CA11: 0 | CB11: 0 | CC11: 0 | CD11: 0 | CE11: 0 | CF11: 0 | CG11: 0 | CH11: 0 | CI11: 0 | CJ11: 0 | CK11: 0 | CL11: 0 | CM11: 0 | CN11: 0 | CO11: 0 | CP11: 0 | CQ11: 0 | CR11: 0 | CS11: 0 | CT11: 0 | CU11: 0 | CV11: 0 | CW11: 0
A12: AT | B12: 0 | C12: 0 | D12: 0 | E12: 0 | F12: 0 | G12: 0 | H12: 0 | I12: 0 | J12: 0 | K12: =MAX('HYPR-S0'!K12,'HYPR-S1'!K$75) -> 17.911437 | L12: =MAX('HYPR-S0'!L12,'HYPR-S1'!L$75) -> 24.644988 | M12: =MAX('HYPR-S0'!M12,'HYPR-S1'!M$75) -> 9.6709922 | N12: =MAX('HYPR-S0'!N12,'HYPR-S1'!N$75) -> 6.2699024 | O12: =MAX('HYPR-S0'!O12,'HYPR-S1'!O$75) -> 7.0097019 | P12: =MAX('HYPR-S0'!P12,'HYPR-S1'!P$75) -> 7.9772951 | Q12: =MAX('HYPR-S0'!Q12,'HYPR-S1'!Q$75) -> 6.1431508 | R12: =MAX('HYPR-S0'!R12,'HYPR-S1'!R$75) -> 5.8558704 | ... AY12: =MAX('HYPR-S0'!AY12,'HYPR-S1'!AY$75) -> 193.84615 | AZ12: 0 | BA12: 0 | BB12: 0 | BC12: 0 | BD12: 0 | BE12: 0 | BF12: 0 | BG12: 0 | BH12: 0 | BI12: 0 | BJ12: 0 | BK12: 0 | BL12: 0 | BM12: 0 | BN12: 0 | BO12: 0 | BP12: 0 | BQ12: 0 | BR12: 0 | BS12: 0 | BT12: 0 | BU12: 0 | BV12: 0 | BW12: 0 | BX12: 0 | BY12: 0 | BZ12: 0 | CA12: 0 | CB12: 0 | CC12: 0 | CD12: 0 | CE12: 0 | CF12: 0 | CG12: 0 | CH12: 0 | CI12: 0 | CJ12: 0 | CK12: 0 | CL12: 0 | CM12: 0 | CN12: 0 | CO12: 0 | CP12: 0 | CQ12: 0 | CR12: 0 | CS12: 0 | CT12: 0 | CU12: 0 | CV12: 0 | CW12: 0
A13: PT | B13: 0 | C13: 0 | D13: 0 | E13: 0 | F13: 0 | G13: 0 | H13: 0 | I13: 0 | J13: 0 | K13: =MAX('HYPR-S0'!K13,'HYPR-S1'!K$75) -> 17.911437 | L13: =MAX('HYPR-S0'!L13,'HYPR-S1'!L$75) -> 24.644988 | M13: =MAX('HYPR-S0'!M13,'HYPR-S1'!M$75) -> 9.6709922 | N13: =MAX('HYPR-S0'!N13,'HYPR-S1'!N$75) -> 6.2699024 | O13: =MAX('HYPR-S0'!O13,'HYPR-S1'!O$75) -> 7.0097019 | P13: =MAX('HYPR-S0'!P13,'HYPR-S1'!P$75) -> 7.9772951 | Q13: =MAX('HYPR-S0'!Q13,'HYPR-S1'!Q$75) -> 6.1431508 | R13: =MAX('HYPR-S0'!R13,'HYPR-S1'!R$75) -> 5.8558704 | ... AY13: =MAX('HYPR-S0'!AY13,'HYPR-S1'!AY$75) -> 193.84615 | AZ13: 0 | BA13: 0 | BB13: 0 | BC13: 0 | BD13: 0 | BE13: 0 | BF13: 0 | BG13: 0 | BH13: 0 | BI13: 0 | BJ13: 0 | BK13: 0 | BL13: 0 | BM13: 0 | BN13: 0 | BO13: 0 | BP13: 0 | BQ13: 0 | BR13: 0 | BS13: 0 | BT13: 0 | BU13: 0 | BV13: 0 | BW13: 0 | BX13: 0 | BY13: 0 | BZ13: 0 | CA13: 0 | CB13: 0 | CC13: 0 | CD13: 0 | CE13: 0 | CF13: 0 | CG13: 0 | CH13: 0 | CI13: 0 | CJ13: 0 | CK13: 0 | CL13: 0 | CM13: 0 | CN13: 0 | CO13: 0 | CP13: 0 | CQ13: 0 | CR13: 0 | CS13: 0 | CT13: 0 | CU13: 0 | CV13: 0 | CW13: 0
... A72: PK | B72: 0 | C72: 0 | D72: 0 | E72: 0 | F72: 0 | G72: 0 | H72: 0 | I72: 0 | J72: 0 | K72: =MAX('HYPR-S0'!K72,'HYPR-S1'!K$75) -> 0 | L72: =MAX('HYPR-S0'!L72,'HYPR-S1'!L$75) -> 0 | M72: =MAX('HYPR-S0'!M72,'HYPR-S1'!M$75) -> 0 | N72: =MAX('HYPR-S0'!N72,'HYPR-S1'!N$75) -> 0 | O72: =MAX('HYPR-S0'!O72,'HYPR-S1'!O$75) -> 0 | P72: =MAX('HYPR-S0'!P72,'HYPR-S1'!P$75) -> 0 | Q72: =MAX('HYPR-S0'!Q72,'HYPR-S1'!Q$75) -> 0 | R72: =MAX('HYPR-S0'!R72,'HYPR-S1'!R$75) -> 0 | ... AY72: =MAX('HYPR-S0'!AY72,'HYPR-S1'!AY$75) -> 193.84615 | AZ72: 0 | BA72: 0 | BB72: 0 | BC72: 0 | BD72: 0 | BE72: 0 | BF72: 0 | BG72: 0 | BH72: 0 | BI72: 0 | BJ72: 0 | BK72: 0 | BL72: 0 | BM72: 0 | BN72: 0 | BO72: 0 | BP72: 0 | BQ72: 0 | BR72: 0 | BS72: 0 | BT72: 0 | BU72: 0 | BV72: 0 | BW72: 0 | BX72: 0 | BY72: 0 | BZ72: 0 | CA72: 0 | CB72: 0 | CC72: 0 | CD72: 0 | CE72: 0 | CF72: 0 | CG72: 0 | CH72: 0 | CI72: 0 | CJ72: 0 | CK72: 0 | CL72: 0 | CM72: 0 | CN72: 0 | CO72: 0 | CP72: 0 | CQ72: 0 | CR72: 0 | CS72: 0 | CT72: 0 | CU72: 0 | CV72: 0 | CW72: 0
A75: Global carbon price | Z75: 0 | AA75: 7.7538462 | AB75: 15.507692 | AC75: 23.261538 | AD75: 31.015385 | AE75: 38.769231 | AF75: 46.523077 | AG75: 54.276923 | AH75: 62.030769 | AI75: 69.784615 | AJ75: 77.538462 | AK75: 85.292308 | AL75: 93.046154 | AM75: 100.8 | AN75: 108.55385 | AO75: 116.30769 | AP75: 124.06154 | AQ75: 131.81538 | AR75: 139.56923 | AS75: 147.32308 | AT75: 155.07692 | AU75: 162.83077 | AV75: 170.58462 | AW75: 178.33846 | AX75: 186.09231 | AY75: 193.84615

Sheet HYPR-S2
B1: 2001 | C1: 2002 | D1: 2003 | E1: 2004 | F1: 2005 | G1: 2006 | H1: 2007 | I1: 2008 | J1: 2009 | K1: 2010 | L1: 2011 | M1: 2012 | N1: 2013 | O1: 2014 | P1: 2015 | Q1: 2016 | R1: 2017 | S1: 2018 | T1: 2019 | U1: 2020 | V1: 2021 | W1: 2022 | X1: 2023 | Y1: 2024 | Z1: 2025 | AA1: 2026 | AB1: 2027 | AC1: 2028 | AD1: 2029 | AE1: 2030 | AF1: 2031 | AG1: 2032 | AH1: 2033 | AI1: 2034 | AJ1: 2035 | AK1: 2036 | AL1: 2037 | AM1: 2038 | AN1: 2039 | AO1: 2040 | AP1: 2041 | AQ1: 2042 | AR1: 2043 | AS1: 2044 | AT1: 2045 | AU1: 2046 | AV1: 2047 | AW1: 2048 | AX1: 2049 | AY1: 2050 | AZ1: 2051 | BA1: 2052 | BB1: 2053 | BC1: 2054 | BD1: 2055 | BE1: 2056 | BF1: 2057 | BG1: 2058 | BH1: 2059 | BI1: 2060 | BJ1: 2061 | BK1: 2062 | BL1: 2063 | BM1: 2064 | BN1: 2065 | BO1: 2066 | BP1: 2067 | BQ1: 2068 | BR1: 2069 | BS1: 2070 | BT1: 2071 | BU1: 2072 | BV1: 2073 | BW1: 2074 | BX1: 2075 | BY1: 2076 | BZ1: 2077 | CA1: 2078 | CB1: 2079 | CC1: 2080 | CD1: 2081 | CE1: 2082 | CF1: 2083 | CG1: 2084 | CH1: 2085 | CI1: 2086 | CJ1: 2087 | CK1: 2088 | CL1: 2089 | CM1: 2090 | CN1: 2091 | CO1: 2092 | CP1: 2093 | CQ1: 2094 | CR1: 2095 | CS1: 2096 | CT1: 2097 | CU1: 2098 | CV1: 2099 | CW1: 2100
A2: BE | B2: 0 | C2: 0 | D2: 0 | E2: 0 | F2: 0 | G2: 0 | H2: 0 | I2: 0 | J2: 0 | K2: 17.911437 | L2: 24.644988 | M2: 9.6709922 | N2: 6.2699024 | O2: 7.0097019 | P2: 7.9772951 | Q2: 6.1431508 | R2: 5.8558704 | S2: 16.87171 | T2: 25.421822 | U2: 19.229474 | V2: 51.640468 | W2: 89.760731 | X2: 99.89806 | Y2: 63.593197 | Z2: 73.000779 | AA2: 77.300934 | AB2: 81.60109 | AC2: 85.901246 | AD2: 90.201402 | AE2: 94.501558 | AF2: 98.801713 | AG2: 103.10187 | AH2: 107.40202 | AI2: 111.70218 | AJ2: 116.00233 | AK2: 120.3025 | AL2: 124.60265 | AM2: 128.90281 | AN2: 133.20296 | AO2: 137.50312 | AP2: 141.80327 | AQ2: 146.10343 | AR2: 150.40358 | AS2: 154.70374 | AT2: 159.00389 | AU2: 163.30405 | AV2: 167.6042 | AW2: 171.90436 | AX2: 176.20451 | AY2: 180.50467 | AZ2: 0 | BA2: 0 | BB2: 0 | BC2: 0 | BD2: 0 | BE2: 0 | BF2: 0 | BG2: 0 | BH2: 0 | BI2: 0 | BJ2: 0 | BK2: 0 | BL2: 0 | BM2: 0 | BN2: 0 | BO2: 0 | BP2: 0 | BQ2: 0 | BR2: 0 | BS2: 0 | BT2: 0 | BU2: 0 | BV2: 0 | BW2: 0 | BX2: 0 | BY2: 0 | BZ2: 0 | CA2: 0 | CB2: 0 | CC2: 0 | CD2: 0 | CE2: 0 | CF2: 0 | CG2: 0 | CH2: 0 | CI2: 0 | CJ2: 0 | CK2: 0 | CL2: 0 | CM2: 0 | CN2: 0 | CO2: 0 | CP2: 0 | CQ2: 0 | CR2: 0 | CS2: 0 | CT2: 0 | CU2: 0 | CV2: 0 | CW2: 0
