Workbook

Sheet Indirect NH3 demand sources
B1: 2010 | C1: 2011 | D1: 2012 | E1: 2013 | F1: 2014 | G1: 2015 | H1: 2016 | I1: 2017 | J1: 2018 | K1: 2019 | L1: 2020 | M1: 2021 | N1: 2022 | O1: 2023 | P1: 2024 | Q1: 2025 | R1: 2026 | S1: 2027 | T1: 2028 | U1: 2029 | V1: 2030 | W1: 2031 | X1: 2032 | Y1: 2033 | Z1: 2034 | AA1: 2035 | AB1: 2036 | AC1: 2037 | AD1: 2038 | AE1: 2039 | AF1: 2040 | AG1: 2041 | AH1: 2042 | AI1: 2043 | AJ1: 2044 | AK1: 2045 | AL1: 2046 | AM1: 2047 | AN1: 2048 | AO1: 2049 | AP1: 2050 | AQ1: 2051 | AR1: 2052 | AS1: 2053 | AT1: 2054 | AU1: 2055 | AV1: 2056 | AW1: 2057 | AX1: 2058 | AY1: 2059 | AZ1: 2060 | BA1: 2061 | BB1: 2062 | BC1: 2063 | BD1: 2064 | BE1: 2065 | BF1: 2066 | BG1: 2067 | BH1: 2068 | BI1: 2069 | BJ1: 2070 | BK1: 2071 | BL1: 2072 | BM1: 2073 | BN1: 2074 | BO1: 2075 | BP1: 2076 | BQ1: 2077 | BR1: 2078 | BS1: 2079 | BT1: 2080 | BU1: 2081 | BV1: 2082 | BW1: 2083 | BX1: 2084 | BY1: 2085 | BZ1: 2086 | CA1: 2087 | CB1: 2088 | CC1: 2089 | CD1: 2090 | CE1: 2091 | CF1: 2092 | CG1: 2093 | CH1: 2094 | CI1: 2095 | CJ1: 2096 | CK1: 2097 | CL1: 2098 | CM1: 2099 | CN1: 2100
A2: Agriculture / Industrial | B2: 0 | C2: 0 | D2: 0 | E2: 0 | F2: 0 | G2: 0 | H2: 0 | I2: 0 | J2: 0 | K2: 0 | L2: 0 | M2: 184 | N2: =$M$2 + ($V$2 - $M$2) / 9 -> 185.55556 | O2: =$N$2 + ($V$2 - $M$2) / 9 -> 187.11111 | P2: =$O$2 + ($V$2 - $M$2) / 9 -> 188.66667 | Q2: =$P$2 + ($V$2 - $M$2) / 9 -> 190.22222 | R2: =$Q$2 + ($V$2 - $M$2) / 9 -> 191.77778 | S2: =$R$2 + ($V$2 - $M$2) / 9 -> 193.33333 | T2: =$S$2 + ($V$2 - $M$2) / 9 -> 194.88889 | U2: =$T$2 + ($V$2 - $M$2) / 9 -> 196.44444 | V2: 198 | W2: =$V$2 + ($AF$2 - $V$2) / 10 -> 199.6 | X2: =$W$2 + ($AF$2 - $V$2) / 10 -> 201.2 | Y2: =$X$2 + ($AF$2 - $V$2) / 10 -> 202.8 | Z2: =$Y$2 + ($AF$2 - $V$2) / 10 -> 204.4 | AA2: =$Z$2 + ($AF$2 - $V$2) / 10 -> 206 | AB2: =$AA$2 + ($AF$2 - $V$2) / 10 -> 207.6 | AC2: =$AB$2 + ($AF$2 - $V$2) / 10 -> 209.2 | AD2: =$AC$2 + ($AF$2 - $V$2) / 10 -> 210.8 | AE2: =$AD$2 + ($AF$2 - $V$2) / 10 -> 212.4 | AF2: 214 | AG2: =$AF$2 + ($AP$2 - $AF$2) / 10 -> 215.8 | AH2: =$AG$2 + ($AP$2 - $AF$2) / 10 -> 217.6 | AI2: =$AH$2 + ($AP$2 - $AF$2) / 10 -> 219.4 | AJ2: =$AI$2 + ($AP$2 - $AF$2) / 10 -> 221.2 | AK2: =$AJ$2 + ($AP$2 - $AF$2) / 10 -> 223 | AL2: =$AK$2 + ($AP$2 - $AF$2) / 10 -> 224.8 | AM2: =$AL$2 + ($AP$2 - $AF$2) / 10 -> 226.6 | AN2: =$AM$2 + ($AP$2 - $AF$2) / 10 -> 228.4 | AO2: =$AN$2 + ($AP$2 - $AF$2) / 10 -> 230.2 | AP2: 232 | AQ2: =$AP$2 + ($CN$2 - $AP$2) / 50 -> 232 | AR2: =$AQ$2 + ($CN$2 - $AP$2) / 50 -> 232 | AS2: =$AR$2 + ($CN$2 - $AP$2) / 50 -> 232 | AT2: =$AS$2 + ($CN$2 - $AP$2) / 50 -> 232 | AU2: =$AT$2 + ($CN$2 - $AP$2) / 50 -> 232 | AV2: =$AU$2 + ($CN$2 - $AP$2) / 50 -> 232 | AW2: =$AV$2 + ($CN$2 - $AP$2) / 50 -> 232 | AX2: =$AW$2 + ($CN$2 - $AP$2) / 50 -> 232 | AY2: =$AX$2 + ($CN$2 - $AP$2) / 50 -> 232 | AZ2: =$AY$2 + ($CN$2 - $AP$2) / 50 -> 232 | BA2: =$AZ$2 + ($CN$2 - $AP$2) / 50 -> 232 | BB2: =$BA$2 + ($CN$2 - $AP$2) / 50 -> 232 | BC2: =$BB$2 + ($CN$2 - $AP$2) / 50 -> 232 | BD2: =$BC$2 + ($CN$2 - $AP$2) / 50 -> 232 | BE2: =$BD$2 + ($CN$2 - $AP$2) / 50 -> 232 | BF2: =$BE$2 + ($CN$2 - $AP$2) / 50 -> 232 | BG2: =$BF$2 + ($CN$2 - $AP$2) / 50 -> 232 | BH2: =$BG$2 + ($CN$2 - $AP$2) / 50 -> 232 | BI2: =$BH$2 + ($CN$2 - $AP$2) / 50 -> 232 | BJ2: =$BI$2 + ($CN$2 - $AP$2) / 50 -> 232 | BK2: =$BJ$2 + ($CN$2 - $AP$2) / 50 -> 232 | BL2: =$BK$2 + ($CN$2 - $AP$2) / 50 -> 232 | BM2: =$BL$2 + ($CN$2 - $AP$2) / 50 -> 232 | BN2: =$BM$2 + ($CN$2 - $AP$2) / 50 -> 232 | BO2: =$BN$2 + ($CN$2 - $AP$2) / 50 -> 232 | BP2: =$BO$2 + ($CN$2 - $AP$2) / 50 -> 232 | BQ2: =$BP$2 + ($CN$2 - $AP$2) / 50 -> 232 | BR2: =$BQ$2 + ($CN$2 - $AP$2) / 50 -> 232 | BS2: =$BR$2 + ($CN$2 - $AP$2) / 50 -> 232 | BT2: =$BS$2 + ($CN$2 - $AP$2) / 50 -> 232 | BU2: =$BT$2 + ($CN$2 - $AP$2) / 50 -> 232 | BV2: =$BU$2 + ($CN$2 - $AP$2) / 50 -> 232 | BW2: =$BV$2 + ($CN$2 - $AP$2) / 50 -> 232 | BX2: =$BW$2 + ($CN$2 - $AP$2) / 50 -> 232 | BY2: =$BX$2 + ($CN$2 - $AP$2) / 50 -> 232 | BZ2: =$BY$2 + ($CN$2 - $AP$2) / 50 -> 232 | CA2: =$BZ$2 + ($CN$2 - $AP$2) / 50 -> 232 | CB2: =$CA$2 + ($CN$2 - $AP$2) / 50 -> 232 | CC2: =$CB$2 + ($CN$2 - $AP$2) / 50 -> 232 | CD2: =$CC$2 + ($CN$2 - $AP$2) / 50 -> 232 | CE2: =$CD$2 + ($CN$2 - $AP$2) / 50 -> 232 | CF2: =$CE$2 + ($CN$2 - $AP$2) / 50 -> 232 | CG2: =$CF$2 + ($CN$2 - $AP$2) / 50 -> 232 | CH2: =$CG$2 + ($CN$2 - $AP$2) / 50 -> 232 | CI2: =$CH$2 + ($CN$2 - $AP$2) / 50 -> 232 | CJ2: =$CI$2 + ($CN$2 - $AP$2) / 50 -> 232 | CK2: =$CJ$2 + ($CN$2 - $AP$2) / 50 -> 232 | CL2: =$CK$2 + ($CN$2 - $AP$2) / 50 -> 232 | CM2: =$CL$2 + ($CN$2 - $AP$2) / 50 -> 232 | CN2: 232
A3: Shipping fuel | B3: 0 | C3: =$B$3 + ($M$3 - $B$3) / 11 -> 0 | D3: =$C$3 + ($M$3 - $B$3) / 11 -> 0 | E3: =$D$3 + ($M$3 - $B$3) / 11 -> 0 | F3: =$E$3 + ($M$3 - $B$3) / 11 -> 0 | G3: =$F$3 + ($M$3 - $B$3) / 11 -> 0 | H3: =$G$3 + ($M$3 - $B$3) / 11 -> 0 | I3: =$H$3 + ($M$3 - $B$3) / 11 -> 0 | J3: =$I$3 + ($M$3 - $B$3) / 11 -> 0 | K3: =$J$3 + ($M$3 - $B$3) / 11 -> 0 | L3: =$K$3 + ($M$3 - $B$3) / 11 -> 0 | M3: 0 | N3: 0 | O3: 0 | P3: 0 | Q3: 0 | R3: =$Q$3 + ($V$3 - $Q$3) / 5 -> 0.6 | S3: =$R$3 + ($V$3 - $Q$3) / 5 -> 1.2 | T3: =$S$3 + ($V$3 - $Q$3) / 5 -> 1.8 | U3: =$T$3 + ($V$3 - $Q$3) / 5 -> 2.4 | V3: 3 | W3: =$V$3 + ($AF$3 - $V$3) / 10 -> 8 | X3: =$W$3 + ($AF$3 - $V$3) / 10 -> 13 | Y3: =$X$3 + ($AF$3 - $V$3) / 10 -> 18 | Z3: =$Y$3 + ($AF$3 - $V$3) / 10 -> 23 | AA3: =$Z$3 + ($AF$3 - $V$3) / 10 -> 28 | AB3: =$AA$3 + ($AF$3 - $V$3) / 10 -> 33 | AC3: =$AB$3 + ($AF$3 - $V$3) / 10 -> 38 | AD3: =$AC$3 + ($AF$3 - $V$3) / 10 -> 43 | AE3: =$AD$3 + ($AF$3 - $V$3) / 10 -> 48 | AF3: 53 | AG3: =$AF$3 + ($AP$3 - $AF$3) / 10 -> 65.9 | AH3: =$AG$3 + ($AP$3 - $AF$3) / 10 -> 78.8 | AI3: =$AH$3 + ($AP$3 - $AF$3) / 10 -> 91.7 | AJ3: =$AI$3 + ($AP$3 - $AF$3) / 10 -> 104.6 | AK3: =$AJ$3 + ($AP$3 - $AF$3) / 10 -> 117.5 | AL3: =$AK$3 + ($AP$3 - $AF$3) / 10 -> 130.4 | AM3: =$AL$3 + ($AP$3 - $AF$3) / 10 -> 143.3 | AN3: =$AM$3 + ($AP$3 - $AF$3) / 10 -> 156.2 | AO3: =$AN$3 + ($AP$3 - $AF$3) / 10 -> 169.1 | AP3: 182 | AQ3: =$AP$3 + ($CN$3 - $AP$3) / 50 -> 182 | AR3: =$AQ$3 + ($CN$3 - $AP$3) / 50 -> 182 | AS3: =$AR$3 + ($CN$3 - $AP$3) / 50 -> 182 | AT3: =$AS$3 + ($CN$3 - $AP$3) / 50 -> 182 | AU3: =$AT$3 + ($CN$3 - $AP$3) / 50 -> 182 | AV3: =$AU$3 + ($CN$3 - $AP$3) / 50 -> 182 | AW3: =$AV$3 + ($CN$3 - $AP$3) / 50 -> 182 | AX3: =$AW$3 + ($CN$3 - $AP$3) / 50 -> 182 | AY3: =$AX$3 + ($CN$3 - $AP$3) / 50 -> 182 | AZ3: =$AY$3 + ($CN$3 - $AP$3) / 50 -> 182 | BA3: =$AZ$3 + ($CN$3 - $AP$3) / 50 -> 182 | BB3: =$BA$3 + ($CN$3 - $AP$3) / 50 -> 182 | BC3: =$BB$3 + ($CN$3 - $AP$3) / 50 -> 182 | BD3: =$BC$3 + ($CN$3 - $AP$3) / 50 -> 182 | BE3: =$BD$3 + ($CN$3 - $AP$3) / 50 -> 182 | BF3: =$BE$3 + ($CN$3 - $AP$3) / 50 -> 182 | BG3: =$BF$3 + ($CN$3 - $AP$3) / 50 -> 182 | BH3: =$BG$3 + ($CN$3 - $AP$3) / 50 -> 182 | BI3: =$BH$3 + ($CN$3 - $AP$3) / 50 -> 182 | BJ3: =$BI$3 + ($CN$3 - $AP$3) / 50 -> 182 | BK3: =$BJ$3 + ($CN$3 - $AP$3) / 50 -> 182 | BL3: =$BK$3 + ($CN$3 - $AP$3) / 50 -> 182 | BM3: =$BL$3 + ($CN$3 - $AP$3) / 50 -> 182 | BN3: =$BM$3 + ($CN$3 - $AP$3) / 50 -> 182 | BO3: =$BN$3 + ($CN$3 - $AP$3) / 50 -> 182 | BP3: =$BO$3 + ($CN$3 - $AP$3) / 50 -> 182 | BQ3: =$BP$3 + ($CN$3 - $AP$3) / 50 -> 182 | BR3: =$BQ$3 + ($CN$3 - $AP$3) / 50 -> 182 | BS3: =$BR$3 + ($CN$3 - $AP$3) / 50 -> 182 | BT3: =$BS$3 + ($CN$3 - $AP$3) / 50 -> 182 | BU3: =$BT$3 + ($CN$3 - $AP$3) / 50 -> 182 | BV3: =$BU$3 + ($CN$3 - $AP$3) / 50 -> 182 | BW3: =$BV$3 + ($CN$3 - $AP$3) / 50 -> 182 | BX3: =$BW$3 + ($CN$3 - $AP$3) / 50 -> 182 | BY3: =$BX$3 + ($CN$3 - $AP$3) / 50 -> 182 | BZ3: =$BY$3 + ($CN$3 - $AP$3) / 50 -> 182 | CA3: =$BZ$3 + ($CN$3 - $AP$3) / 50 -> 182 | CB3: =$CA$3 + ($CN$3 - $AP$3) / 50 -> 182 | CC3: =$CB$3 + ($CN$3 - $AP$3) / 50 -> 182 | CD3: =$CC$3 + ($CN$3 - $AP$3) / 50 -> 182 | CE3: =$CD$3 + ($CN$3 - $AP$3) / 50 -> 182 | CF3: =$CE$3 + ($CN$3 - $AP$3) / 50 -> 182 | CG3: =$CF$3 + ($CN$3 - $AP$3) / 50 -> 182 | CH3: =$CG$3 + ($CN$3 - $AP$3) / 50 -> 182 | CI3: =$CH$3 + ($CN$3 - $AP$3) / 50 -> 182 | CJ3: =$CI$3 + ($CN$3 - $AP$3) / 50 -> 182 | CK3: =$CJ$3 + ($CN$3 - $AP$3) / 50 -> 182 | CL3: =$CK$3 + ($CN$3 - $AP$3) / 50 -> 182 | CM3: =$CL$3 + ($CN$3 - $AP$3) / 50 -> 182 | CN3: 182
A4: Hydrogen carrier | B4: 0 | C4: =$B$4 + ($M$4 - $B$4) / 11 -> 0 | D4: =$C$4 + ($M$4 - $B$4) / 11 -> 0 | E4: =$D$4 + ($M$4 - $B$4) / 11 -> 0 | F4: =$E$4 + ($M$4 - $B$4) / 11 -> 0 | G4: =$F$4 + ($M$4 - $B$4) / 11 -> 0 | H4: =$G$4 + ($M$4 - $B$4) / 11 -> 0 | I4: =$H$4 + ($M$4 - $B$4) / 11 -> 0 | J4: =$I$4 + ($M$4 - $B$4) / 11 -> 0 | K4: =$J$4 + ($M$4 - $B$4) / 11 -> 0 | L4: =$K$4 + ($M$4 - $B$4) / 11 -> 0 | M4: 0 | N4: 0 | O4: 0 | P4: 0 | Q4: 0 | R4: =$Q$4 + ($V$4 - $Q$4) / 5 -> 0 | S4: =$R$4 + ($V$4 - $Q$4) / 5 -> 0 | T4: =$S$4 + ($V$4 - $Q$4) / 5 -> 0 | U4: =$T$4 + ($V$4 - $Q$4) / 5 -> 0 | V4: 0 | W4: =$V$4 + ($AF$4 - $V$4) / 10 -> 1.5 | X4: =$W$4 + ($AF$4 - $V$4) / 10 -> 3 | Y4: =$X$4 + ($AF$4 - $V$4) / 10 -> 4.5 | Z4: =$Y$4 + ($AF$4 - $V$4) / 10 -> 6 | AA4: =$Z$4 + ($AF$4 - $V$4) / 10 -> 7.5 | AB4: =$AA$4 + ($AF$4 - $V$4) / 10 -> 9 | AC4: =$AB$4 + ($AF$4 - $V$4) / 10 -> 10.5 | AD4: =$AC$4 + ($AF$4 - $V$4) / 10 -> 12 | AE4: =$AD$4 + ($AF$4 - $V$4) / 10 -> 13.5 | AF4: 15 | AG4: =$AF$4 + ($AP$4 - $AF$4) / 10 -> 17.1 | AH4: =$AG$4 + ($AP$4 - $AF$4) / 10 -> 19.2 | AI4: =$AH$4 + ($AP$4 - $AF$4) / 10 -> 21.3 | AJ4: =$AI$4 + ($AP$4 - $AF$4) / 10 -> 23.4 | AK4: =$AJ$4 + ($AP$4 - $AF$4) / 10 -> 25.5 | AL4: =$AK$4 + ($AP$4 - $AF$4) / 10 -> 27.6 | AM4: =$AL$4 + ($AP$4 - $AF$4) / 10 -> 29.7 | AN4: =$AM$4 + ($AP$4 - $AF$4) / 10 -> 31.8 | AO4: =$AN$4 + ($AP$4 - $AF$4) / 10 -> 33.9 | AP4: 36 | AQ4: =$AP$4 + ($CN$4 - $AP$4) / 50 -> 36 | AR4: =$AQ$4 + ($CN$4 - $AP$4) / 50 -> 36 | AS4: =$AR$4 + ($CN$4 - $AP$4) / 50 -> 36 | AT4: =$AS$4 + ($CN$4 - $AP$4) / 50 -> 36 | AU4: =$AT$4 + ($CN$4 - $AP$4) / 50 -> 36 | AV4: =$AU$4 + ($CN$4 - $AP$4) / 50 -> 36 | AW4: =$AV$4 + ($CN$4 - $AP$4) / 50 -> 36 | AX4: =$AW$4 + ($CN$4 - $AP$4) / 50 -> 36 | AY4: =$AX$4 + ($CN$4 - $AP$4) / 50 -> 36 | AZ4: =$AY$4 + ($CN$4 - $AP$4) / 50 -> 36 | BA4: =$AZ$4 + ($CN$4 - $AP$4) / 50 -> 36 | BB4: =$BA$4 + ($CN$4 - $AP$4) / 50 -> 36 | BC4: =$BB$4 + ($CN$4 - $AP$4) / 50 -> 36 | BD4: =$BC$4 + ($CN$4 - $AP$4) / 50 -> 36 | BE4: =$BD$4 + ($CN$4 - $AP$4) / 50 -> 36 | BF4: =$BE$4 + ($CN$4 - $AP$4) / 50 -> 36 | BG4: =$BF$4 + ($CN$4 - $AP$4) / 50 -> 36 | BH4: =$BG$4 + ($CN$4 - $AP$4) / 50 -> 36 | BI4: =$BH$4 + ($CN$4 - $AP$4) / 50 -> 36 | BJ4: =$BI$4 + ($CN$4 - $AP$4) / 50 -> 36 | BK4: =$BJ$4 + ($CN$4 - $AP$4) / 50 -> 36 | BL4: =$BK$4 + ($CN$4 - $AP$4) / 50 -> 36 | BM4: =$BL$4 + ($CN$4 - $AP$4) / 50 -> 36 | BN4: =$BM$4 + ($CN$4 - $AP$4) / 50 -> 36 | BO4: =$BN$4 + ($CN$4 - $AP$4) / 50 -> 36 | BP4: =$BO$4 + ($CN$4 - $AP$4) / 50 -> 36 | BQ4: =$BP$4 + ($CN$4 - $AP$4) / 50 -> 36 | BR4: =$BQ$4 + ($CN$4 - $AP$4) / 50 -> 36 | BS4: =$BR$4 + ($CN$4 - $AP$4) / 50 -> 36 | BT4: =$BS$4 + ($CN$4 - $AP$4) / 50 -> 36 | BU4: =$BT$4 + ($CN$4 - $AP$4) / 50 -> 36 | BV4: =$BU$4 + ($CN$4 - $AP$4) / 50 -> 36 | BW4: =$BV$4 + ($CN$4 - $AP$4) / 50 -> 36 | BX4: =$BW$4 + ($CN$4 - $AP$4) / 50 -> 36 | BY4: =$BX$4 + ($CN$4 - $AP$4) / 50 -> 36 | BZ4: =$BY$4 + ($CN$4 - $AP$4) / 50 -> 36 | CA4: =$BZ$4 + ($CN$4 - $AP$4) / 50 -> 36 | CB4: =$CA$4 + ($CN$4 - $AP$4) / 50 -> 36 | CC4: =$CB$4 + ($CN$4 - $AP$4) / 50 -> 36 | CD4: =$CC$4 + ($CN$4 - $AP$4) / 50 -> 36 | CE4: =$CD$4 + ($CN$4 - $AP$4) / 50 -> 36 | CF4: =$CE$4 + ($CN$4 - $AP$4) / 50 -> 36 | CG4: =$CF$4 + ($CN$4 - $AP$4) / 50 -> 36 | CH4: =$CG$4 + ($CN$4 - $AP$4) / 50 -> 36 | CI4: =$CH$4 + ($CN$4 - $AP$4) / 50 -> 36 | CJ4: =$CI$4 + ($CN$4 - $AP$4) / 50 -> 36 | CK4: =$CJ$4 + ($CN$4 - $AP$4) / 50 -> 36 | CL4: =$CK$4 + ($CN$4 - $AP$4) / 50 -> 36 | CM4: =$CL$4 + ($CN$4 - $AP$4) / 50 -> 36 | CN4: 36
A5: Power generation | B5: 0 | C5: =$B$5 + ($M$5 - $B$5) / 11 -> 0 | D5: =$C$5 + ($M$5 - $B$5) / 11 -> 0 | E5: =$D$5 + ($M$5 - $B$5) / 11 -> 0 | F5: =$E$5 + ($M$5 - $B$5) / 11 -> 0 | G5: =$F$5 + ($M$5 - $B$5) / 11 -> 0 | H5: =$G$5 + ($M$5 - $B$5) / 11 -> 0 | I5: =$H$5 + ($M$5 - $B$5) / 11 -> 0 | J5: =$I$5 + ($M$5 - $B$5) / 11 -> 0 | K5: =$J$5 + ($M$5 - $B$5) / 11 -> 0 | L5: =$K$5 + ($M$5 - $B$5) / 11 -> 0 | M5: 0 | N5: 0 | O5: 0 | P5: 0 | Q5: 0 | R5: =$Q$5 + ($V$5 - $Q$5) / 5 -> 0.4 | S5: =$R$5 + ($V$5 - $Q$5) / 5 -> 0.8 | T5: =$S$5 + ($V$5 - $Q$5) / 5 -> 1.2 | U5: =$T$5 + ($V$5 - $Q$5) / 5 -> 1.6 | V5: 2 | W5: =$V$5 + ($AF$5 - $V$5) / 10 -> 3 | X5: =$W$5 + ($AF$5 - $V$5) / 10 -> 4 | Y5: =$X$5 + ($AF$5 - $V$5) / 10 -> 5 | Z5: =$Y$5 + ($AF$5 - $V$5) / 10 -> 6 | AA5: =$Z$5 + ($AF$5 - $V$5) / 10 -> 7 | AB5: =$AA$5 + ($AF$5 - $V$5) / 10 -> 8 | AC5: =$AB$5 + ($AF$5 - $V$5) / 10 -> 9 | AD5: =$AC$5 + ($AF$5 - $V$5) / 10 -> 10 | AE5: =$AD$5 + ($AF$5 - $V$5) / 10 -> 11 | AF5: 12 | AG5: =$AF$5 + ($AP$5 - $AF$5) / 10 -> 12.8 | AH5: =$AG$5 + ($AP$5 - $AF$5) / 10 -> 13.6 | AI5: =$AH$5 + ($AP$5 - $AF$5) / 10 -> 14.4 | AJ5: =$AI$5 + ($AP$5 - $AF$5) / 10 -> 15.2 | AK5: =$AJ$5 + ($AP$5 - $AF$5) / 10 -> 16 | AL5: =$AK$5 + ($AP$5 - $AF$5) / 10 -> 16.8 | AM5: =$AL$5 + ($AP$5 - $AF$5) / 10 -> 17.6 | AN5: =$AM$5 + ($AP$5 - $AF$5) / 10 -> 18.4 | AO5: =$AN$5 + ($AP$5 - $AF$5) / 10 -> 19.2 | AP5: 20 | AQ5: =$AP$5 + ($CN$5 - $AP$5) / 50 -> 20 | AR5: =$AQ$5 + ($CN$5 - $AP$5) / 50 -> 20 | AS5: =$AR$5 + ($CN$5 - $AP$5) / 50 -> 20 | AT5: =$AS$5 + ($CN$5 - $AP$5) / 50 -> 20 | AU5: =$AT$5 + ($CN$5 - $AP$5) / 50 -> 20 | AV5: =$AU$5 + ($CN$5 - $AP$5) / 50 -> 20 | AW5: =$AV$5 + ($CN$5 - $AP$5) / 50 -> 20 | AX5: =$AW$5 + ($CN$5 - $AP$5) / 50 -> 20 | AY5: =$AX$5 + ($CN$5 - $AP$5) / 50 -> 20 | AZ5: =$AY$5 + ($CN$5 - $AP$5) / 50 -> 20 | BA5: =$AZ$5 + ($CN$5 - $AP$5) / 50 -> 20 | BB5: =$BA$5 + ($CN$5 - $AP$5) / 50 -> 20 | BC5: =$BB$5 + ($CN$5 - $AP$5) / 50 -> 20 | BD5: =$BC$5 + ($CN$5 - $AP$5) / 50 -> 20 | BE5: =$BD$5 + ($CN$5 - $AP$5) / 50 -> 20 | BF5: =$BE$5 + ($CN$5 - $AP$5) / 50 -> 20 | BG5: =$BF$5 + ($CN$5 - $AP$5) / 50 -> 20 | BH5: =$BG$5 + ($CN$5 - $AP$5) / 50 -> 20 | BI5: =$BH$5 + ($CN$5 - $AP$5) / 50 -> 20 | BJ5: =$BI$5 + ($CN$5 - $AP$5) / 50 -> 20 | BK5: =$BJ$5 + ($CN$5 - $AP$5) / 50 -> 20 | BL5: =$BK$5 + ($CN$5 - $AP$5) / 50 -> 20 | BM5: =$BL$5 + ($CN$5 - $AP$5) / 50 -> 20 | BN5: =$BM$5 + ($CN$5 - $AP$5) / 50 -> 20 | BO5: =$BN$5 + ($CN$5 - $AP$5) / 50 -> 20 | BP5: =$BO$5 + ($CN$5 - $AP$5) / 50 -> 20 | BQ5: =$BP$5 + ($CN$5 - $AP$5) / 50 -> 20 | BR5: =$BQ$5 + ($CN$5 - $AP$5) / 50 -> 20 | BS5: =$BR$5 + ($CN$5 - $AP$5) / 50 -> 20 | BT5: =$BS$5 + ($CN$5 - $AP$5) / 50 -> 20 | BU5: =$BT$5 + ($CN$5 - $AP$5) / 50 -> 20 | BV5: =$BU$5 + ($CN$5 - $AP$5) / 50 -> 20 | BW5: =$BV$5 + ($CN$5 - $AP$5) / 50 -> 20 | BX5: =$BW$5 + ($CN$5 - $AP$5) / 50 -> 20 | BY5: =$BX$5 + ($CN$5 - $AP$5) / 50 -> 20 | BZ5: =$BY$5 + ($CN$5 - $AP$5) / 50 -> 20 | CA5: =$BZ$5 + ($CN$5 - $AP$5) / 50 -> 20 | CB5: =$CA$5 + ($CN$5 - $AP$5) / 50 -> 20 | CC5: =$CB$5 + ($CN$5 - $AP$5) / 50 -> 20 | CD5: =$CC$5 + ($CN$5 - $AP$5) / 50 -> 20 | CE5: =$CD$5 + ($CN$5 - $AP$5) / 50 -> 20 | CF5: =$CE$5 + ($CN$5 - $AP$5) / 50 -> 20 | CG5: =$CF$5 + ($CN$5 - $AP$5) / 50 -> 20 | CH5: =$CG$5 + ($CN$5 - $AP$5) / 50 -> 20 | CI5: =$CH$5 + ($CN$5 - $AP$5) / 50 -> 20 | CJ5: =$CI$5 + ($CN$5 - $AP$5) / 50 -> 20 | CK5: =$CJ$5 + ($CN$5 - $AP$5) / 50 -> 20 | CL5: =$CK$5 + ($CN$5 - $AP$5) / 50 -> 20 | CM5: =$CL$5 + ($CN$5 - $AP$5) / 50 -> 20 | CN5: 20

Sheet Methanol demand shares
A1: Methanol demand
A2: time | B2: 2010 | C2: 2011 | D2: 2012 | E2: 2013 | F2: 2014 | G2: 2015 | H2: 2016 | I2: 2017 | J2: 2018 | K2: 2019 | L2: 2020 | M2: 2021 | N2: 2022 | O2: 2023 | P2: 2024 | Q2: 2025 | R2: 2026 | S2: 2027 | T2: 2028 | U2: 2029 | V2: 2030 | W2: 2031 | X2: 2032 | Y2: 2033 | Z2: 2034 | AA2: 2035 | AB2: 2036 | AC2: 2037 | AD2: 2038 | AE2: 2039 | AF2: 2040 | AG2: 2041 | AH2: 2042 | AI2: 2043 | AJ2: 2044 | AK2: 2045 | AL2: 2046 | AM2: 2047 | AN2: 2048 | AO2: 2049 | AP2: 2050
A3: Dan_ba_T1-5; 1 Belgium (BE); sum of FUTI | B3: 0 | C3: 0.004718946 | D3: 0.004410226 | E3: 0.004035064 | F3: 0.003665084 | G3: 0.003519368 | H3: 0.003149318 | I3: 0.002947582 | J3: 0.002667751 | K3: 0.002423761 | L3: 0.00210952 | M3: 0.002160653 | N3: 0.001975201 | O3: 0.001861198 | P3: 0.00181609 | Q3: 0.001735243 | R3: 0.001659604 | S3: 0.00158745 | T3: 0.001511456 | U3: 0.00143312 | V3: 0.001382262 | W3: 0.00134174 | X3: 0.001302412 | Y3: 0.00126426 | Z3: 0.001227248 | AA3: 0.001193972 | AB3: 0.00116045 | AC3: 0.001127891 | AD3: 0.001096271 | AE3: 0.001065559 | AF3: 0.001037784 | AG3: 0.001014907 | AH3: 0.000992563 | AI3: 0.000970737 | AJ3: 0.000949415 | AK3: 0.000928337 | AL3: 0.000908247 | AM3: 0.000888457 | AN3: 0.000869077 | AO3: 0.000850113 | AP3: 0.000831611
A4: Dan_ba_T1-5; 2 Denmark (DK); sum of FUTI | B4: 0 | C4: 0.001138045 | D4: 0.001142435 | E4: 0.001101862 | F4: 0.001064539 | G4: 0.001010909 | H4: 0.000960996 | I4: 0.000912351 | J4: 0.000853307 | K4: 0.000783322 | L4: 0.000709113 | M4: 0.000710788 | N4: 0.00065805 | O4: 0.000630553 | P4: 0.000620437 | Q4: 0.000597298 | R4: 0.000575962 | S4: 0.000555842 | T4: 0.000535848 | U4: 0.000514552 | V4: 0.000502183 | W4: 0.000492424 | X4: 0.000483215 | Y4: 0.000474274 | Z4: 0.000465592 | AA4: 0.000457037 | AB4: 0.000448119 | AC4: 0.000439452 | AD4: 0.000431029 | AE4: 0.00042284 | AF4: 0.000415079 | AG4: 0.000409251 | AH4: 0.000403467 | AI4: 0.00039773 | AJ4: 0.000392048 | AK4: 0.000386487 | AL4: 0.000382235 | AM4: 0.00037807 | AN4: 0.000373994 | AO4: 0.000370004 | AP4: 0.000366149
A5: Dan_ba_T1-5; 3 Germany (DE); sum of FUTI | B5: 0 | C5: 0.041400157 | D5: 0.039280533 | E5: 0.03726997 | F5: 0.035363215 | G5: 0.033555163 | H5: 0.032018621 | I5: 0.030545973 | J5: 0.029135233 | K5: 0.027032228 | L5: 0.025274616 | M5: 0.02588292 | N5: 0.02353189 | O5: 0.022939047 | P5: 0.022464085 | Q5: 0.021635465 | R5: 0.020861978 | S5: 0.020056202 | T5: 0.019183283 | U5: 0.018274404 | V5: 0.017692 | W5: 0.017244704 | X5: 0.016811281 | Y5: 0.016391433 | Z5: 0.015984759 | AA5: 0.015634993 | AB5: 0.015238827 | AC5: 0.014854904 | AD5: 0.014482851 | AE5: 0.014122201 | AF5: 0.013803422 | AG5: 0.013526866 | AH5: 0.013257365 | AI5: 0.012994722 | AJ5: 0.012738749 | AK5: 0.012488402 | AL5: 0.012248291 | AM5: 0.012014128 | AN5: 0.011785782 | AO5: 0.011563108 | AP5: 0.011339679
A6: Dan_ba_T1-5; 4 Greece (EL); sum of FUTI | B6: 0 | C6: 0.001359214 | D6: 0.001189884 | E6: 0.001111535 | F6: 0.001040145 | G6: 0.000988267 | H6: 0.000895121 | I6: 0.000842453 | J6: 0.000778514 | K6: 0.000728683 | L6: 0.000700977 | M6: 0.000721508 | N6: 0.000673571 | O6: 0.000622009 | P6: 0.000603607 | Q6: 0.000573637 | R6: 0.000546415 | S6: 0.000520199 | T6: 0.000493835 | U6: 0.000466918 | V6: 0.000449404 | W6: 0.000440819 | X6: 0.000432451 | Y6: 0.000424297 | Z6: 0.000416343 | AA6: 0.000408906 | AB6: 0.000400613 | AC6: 0.000392543 | AD6: 0.00038469 | AE6: 0.000377047 | AF6: 0.00036971 | AG6: 0.000361623 | AH6: 0.00035375 | AI6: 0.000346088 | AJ6: 0.000338629 | AK6: 0.000331336 | AL6: 0.000324343 | AM6: 0.000317536 | AN6: 0.00031091 | AO6: 0.000304461 | AP6: 0.00029816
A7: Dan_ba_T1-5; 5 Spain (ES); sum of FUTI | B7: 0 | C7: 0.009763998 | D7: 0.00915101 | E7: 0.008576631 | F7: 0.008038507 | G7: 0.007534406 | H7: 0.007101634 | I7: 0.006692304 | J7: 0.006305306 | K7: 0.005831649 | L7: 0.00544962 | M7: 0.005907951 | N7: 0.005596354 | O7: 0.004668669 | P7: 0.004581074 | Q7: 0.004411394 | R7: 0.00425148 | S7: 0.004093382 | T7: 0.003932258 | U7: 0.003762321 | V7: 0.003662609 | W7: 0.003588622 | X7: 0.003516464 | Y7: 0.003446149 | Z7: 0.00337766 | AA7: 0.003310886 | AB7: 0.003237065 | AC7: 0.00316517 | AD7: 0.00309516 | AE7: 0.003026966 | AF7: 0.002958259 | AG7: 0.002895545 | AH7: 0.002834409 | AI7: 0.002774815 | AJ7: 0.002716725 | AK7: 0.002658937 | AL7: 0.002611066 | AM7: 0.002564368 | AN7: 0.002518816 | AO7: 0.002474383 | AP7: 0.002431859
A8: Dan_ba_T1-5; 6 France (FR); sum of FUTI | B8: 0 | C8: 0.012825591 | D8: 0.01173809 | E8: 0.010742956 | F8: 0.009832437 | G8: 0.008999398 | H8: 0.008283262 | I8: 0.007622499 | J8: 0.007013045 | K8: 0.006238971 | L8: 0.004818506 | M8: 0.004354779 | N8: 0.004274992 | O8: 0.004610912 | P8: 0.00447386 | Q8: 0.004261641 | R8: 0.00407017 | S8: 0.003881358 | T8: 0.003683631 | U8: 0.003482146 | V8: 0.003352449 | W8: 0.003252349 | X8: 0.003156556 | Y8: 0.003064186 | Z8: 0.00297511 | AA8: 0.002893373 | AB8: 0.002808615 | AC8: 0.002726772 | AD8: 0.002647746 | AE8: 0.002571424 | AF8: 0.002501408 | AG8: 0.002442604 | AH8: 0.002385494 | AI8: 0.002330026 | AJ8: 0.002276152 | AK8: 0.002223173 | AL8: 0.002172402 | AM8: 0.002123079 | AN8: 0.002075166 | AO8: 0.002028625 | AP8: 0.001982734
A9: Dan_ba_T1-5; 7 Ireland (IE); sum of FUTI | B9: 0 | C9: 0.000874622 | D9: 0.000821529 | E9: 0.000741096 | F9: 0.000783573 | G9: 0.001030136 | H9: 0.001092269 | I9: 0.001109382 | J9: 0.001198934 | K9: 0.001194935 | L9: 0.001506846 | M9: 0.002052089 | N9: 0.002030459 | O9: 0.002065637 | P9: 0.002023489 | Q9: 0.00204467 | R9: 0.002071012 | S9: 0.002098446 | T9: 0.002122429 | U9: 0.002138589 | V9: 0.00219224 | W9: 0.002264912 | X9: 0.002340532 | Y9: 0.002419261 | Z9: 0.002501242 | AA9: 0.002587129 | AB9: 0.002672111 | AC9: 0.002760522 | AD9: 0.002852532 | AE9: 0.002948297 | AF9: 0.003047437 | AG9: 0.003162505 | AH9: 0.003282578 | AI9: 0.003407902 | AJ9: 0.003538735 | AK9: 0.003674741 | AL9: 0.003816326 | AM9: 0.003964137 | AN9: 0.004118478 | AO9: 0.004279672 | AP9: 0.004448388
A10: Dan_ba_T1-5; 8 Italy (IT); sum of FUTI | B10: 0 | C10: 0.013945985 | D10: 0.013355258 | E10: 0.012477862 | F10: 0.011661739 | G10: 0.01098478 | H10: 0.010328258 | I10: 0.009886909 | J10: 0.009313645 | K10: 0.008495028 | L10: 0.007320704 | M10: 0.007532617 | N10: 0.007005495 | O10: 0.006663427 | P10: 0.006496291 | Q10: 0.006198207 | R10: 0.005926922 | S10: 0.005659394 | T10: 0.005387559 | U10: 0.00510846 | V10: 0.004924666 | W10: 0.004789727 | X10: 0.004659036 | Y10: 0.00453245 | Z10: 0.004409839 | AA10: 0.004304871 | AB10: 0.004202746 | AC10: 0.004103517 | AD10: 0.004007109 | AE10: 0.003913419 | AF10: 0.003827526 | AG10: 0.003760484 | AH10: 0.003694938 | AI10: 0.003630852 | AJ10: 0.003568196 | AK10: 0.003510499 | AL10: 0.003453216 | AM10: 0.003397233 | AN10: 0.003342539 | AO10: 0.003289112 | AP10: 0.003240091
A11: Dan_ba_T1-5; 9 Luxembourg (LX); sum of FUTI | B11: 0 | C11: 0.000134499 | D11: 0.000130979 | E11: 0.00013249 | F11: 0.000130344 | G11: 0.000123422 | H11: 0.000117625 | I11: 0.000110963 | J11: 0.000104979 | K11: 9.76647e-05 | L11: 8.63719e-05 | M11: 8.46727e-05 | N11: 8.03217e-05 | O11: 7.78552e-05 | P11: 7.69193e-05 | Q11: 7.44073e-05 | R11: 7.21167e-05 | S11: 6.9941e-05 | T11: 6.77248e-05 | U11: 6.53234e-05 | V11: 6.41156e-05 | W11: 6.3613e-05 | X11: 6.31272e-05 | Y11: 6.26585e-05 | Z11: 6.22066e-05 | AA11: 6.17697e-05 | AB11: 6.1166e-05 | AC11: 6.0579e-05 | AD11: 6.00085e-05 | AE11: 5.94536e-05 | AF11: 5.89107e-05 | AG11: 5.84853e-05 | AH11: 5.80713e-05 | AI11: 5.76682e-05 | AJ11: 5.7276e-05 | AK11: 5.68905e-05 | AL11: 5.63646e-05 | AM11: 5.58515e-05 | AN11: 5.53508e-05 | AO11: 5.48622e-05 | AP11: 5.43827e-05
A12: Dan_ba_T1-5; 10 Netherlands (NL); sum of FUTI | B12: 0 | C12: 0.009173203 | D12: 0.009210823 | E12: 0.009248731 | F12: 0.009287031 | G12: 0.009325811 | H12: 0.009417419 | I12: 0.009507915 | J12: 0.009597362 | K12: 0.009249175 | L12: 0.009055986 | M12: 0.009299371 | N12: 0.009298109 | O12: 0.010030419 | P12: 0.00982076 | Q12: 0.009398864 | R12: 0.009022827 | S12: 0.008664493 | T12: 0.008259415 | U12: 0.007841809 | V12: 0.007566189 | W12: 0.007328139 | X12: 0.007090449 | Y12: 0.006855097 | Z12: 0.006621949 | AA12: 0.006407543 | AB12: 0.006220205 | AC12: 0.00603869 | AD12: 0.005862808 | AE12: 0.005692336 | AF12: 0.005547318 | AG12: 0.005433283 | AH12: 0.005321487 | AI12: 0.005211843 | AJ12: 0.005104272 | AK12: 0.005004632 | AL12: 0.004904879 | AM12: 0.004806858 | AN12: 0.004710567 | AO12: 0.004616022 | AP12: 0.0045228
A13: Dan_ba_T1-5; 11 Austria (AT); sum of FUTI | B13: 0 | C13: 0.004064786 | D13: 0.003598802 | E13: 0.0037221 | F13: 0.003741231 | G13: 0.003327408 | H13: 0.003359976 | I13: 0.003114239 | J13: 0.003150503 | K13: 0.002888775 | L13: 0.002517634 | M13: 0.002584936 | N13: 0.002439677 | O13: 0.002338453 | P13: 0.00228874 | Q13: 0.002191082 | R13: 0.002096987 | S13: 0.002007893 | T13: 0.001912051 | U13: 0.0018135 | V13: 0.001748973 | W13: 0.00169343 | X13: 0.001639944 | Y13: 0.001588427 | Z13: 0.001538805 | AA13: 0.001493191 | AB13: 0.001452658 | AC13: 0.001413381 | AD13: 0.001375334 | AE13: 0.001338478 | AF13: 0.001303871 | AG13: 0.001277648 | AH13: 0.001252088 | AI13: 0.001227174 | AJ13: 0.001202891 | AK13: 0.001178204 | AL13: 0.001156387 | AM13: 0.001135113 | AN13: 0.001114371 | AO13: 0.001094147 | AP13: 0.001073822
... A73: Dan_ba_T1-5; 71 Pakistan (PK); sum of FUTI | B73: 0 | C73: 0.000566034 | D73: 0.000553705 | E73: 0.000541654 | F73: 0.000529877 | G73: 0.000518375 | H73: 0.000509975 | I73: 0.000501604 | J73: 0.000493272 | K73: 0.000377517 | L73: 0.000380672 | M73: 0.000393208 | N73: 0.000437215 | O73: 0.000452428 | P73: 0.000452034 | Q73: 0.000438352 | R73: 0.000426785 | S73: 0.00041582 | T73: 0.000406484 | U73: 0.000395522 | V73: 0.000390087 | W73: 0.000386424 | X73: 0.000382662 | Y73: 0.000378833 | Z73: 0.000374955 | AA73: 0.000371015 | AB73: 0.000366472 | AC73: 0.000361923 | AD73: 0.000357382 | AE73: 0.000352859 | AF73: 0.000348343 | AG73: 0.000343381 | AH73: 0.000338511 | AI73: 0.000333735 | AJ73: 0.000329055 | AK73: 0.000324472 | AL73: 0.000319989 | AM73: 0.000315604 | AN73: 0.000311318 | AO73: 0.000307131 | AP73: 0.000303043

Sheet NH3 as trade precursor
A1: Methanol demand
A2: time | B2: 2010 | C2: 2011 | D2: 2012 | E2: 2013 | F2: 2014 | G2: 2015 | H2: 2016 | I2: 2017 | J2: 2018 | K2: 2019 | L2: 2020 | M2: 2021 | N2: 2022 | O2: 2023 | P2: 2024 | Q2: 2025 | R2: 2026 | S2: 2027 | T2: 2028 | U2: 2029 | V2: 2030 | W2: 2031 | X2: 2032 | Y2: 2033 | Z2: 2034 | AA2: 2035 | AB2: 2036 | AC2: 2037 | AD2: 2038 | AE2: 2039 | AF2: 2040 | AG2: 2041 | AH2: 2042 | AI2: 2043 | AJ2: 2044 | AK2: 2045 | AL2: 2046 | AM2: 2047 | AN2: 2048 | AO2: 2049 | AP2: 2050
A3: Dan_ba_T1-5; 1 Belgium (BE); sum of FUTI | B3: ='Methanol demand shares'!B3*'Indirect NH3 demand sources'!B$4 -> 0 | C3: ='Methanol demand shares'!C3*'Indirect NH3 demand sources'!C$4 -> 0 | D3: ='Methanol demand shares'!D3*'Indirect NH3 demand sources'!D$4 -> 0 | E3: ='Methanol demand shares'!E3*'Indirect NH3 demand sources'!E$4 -> 0 | F3: ='Methanol demand shares'!F3*'Indirect NH3 demand sources'!F$4 -> 0 | G3: ='Methanol demand shares'!G3*'Indirect NH3 demand sources'!G$4 -> 0 | H3: ='Methanol demand shares'!H3*'Indirect NH3 demand sources'!H$4 -> 0 | I3: ='Methanol demand shares'!I3*'Indirect NH3 demand sources'!I$4 -> 0 | ... AP3: ='Methanol demand shares'!AP3*'Indirect NH3 demand sources'!AP$4 -> 0.029937996
A4: Dan_ba_T1-5; 2 Denmark (DK); sum of FUTI | B4: ='Methanol demand shares'!B4*'Indirect NH3 demand sources'!B$4 -> 0 | C4: ='Methanol demand shares'!C4*'Indirect NH3 demand sources'!C$4 -> 0 | D4: ='Methanol demand shares'!D4*'Indirect NH3 demand sources'!D$4 -> 0 | E4: ='Methanol demand shares'!E4*'Indirect NH3 demand sources'!E$4 -> 0 | F4: ='Methanol demand shares'!F4*'Indirect NH3 demand sources'!F$4 -> 0 | G4: ='Methanol demand shares'!G4*'Indirect NH3 demand sources'!G$4 -> 0 | H4: ='Methanol demand shares'!H4*'Indirect NH3 demand sources'!H$4 -> 0 | I4: ='Methanol demand shares'!I4*'Indirect NH3 demand sources'!I$4 -> 0 | ... AP4: ='Methanol demand shares'!AP4*'Indirect NH3 demand sources'!AP$4 -> 0.013181364
A5: Dan_ba_T1-5; 3 Germany (DE); sum of FUTI | B5: ='Methanol demand shares'!B5*'Indirect NH3 demand sources'!B$4 -> 0 | C5: ='Methanol demand shares'!C5*'Indirect NH3 demand sources'!C$4 -> 0 | D5: ='Methanol demand shares'!D5*'Indirect NH3 demand sources'!D$4 -> 0 | E5: ='Methanol demand shares'!E5*'Indirect NH3 demand sources'!E$4 -> 0 | F5: ='Methanol demand shares'!F5*'Indirect NH3 demand sources'!F$4 -> 0 | G5: ='Methanol demand shares'!G5*'Indirect NH3 demand sources'!G$4 -> 0 | H5: ='Methanol demand shares'!H5*'Indirect NH3 demand sources'!H$4 -> 0 | I5: ='Methanol demand shares'!I5*'Indirect NH3 demand sources'!I$4 -> 0 | ... AP5: ='Methanol demand shares'!AP5*'Indirect NH3 demand sources'!AP$4 -> 0.40822844
A6: Dan_ba_T1-5; 4 Greece (EL); sum of FUTI | B6: ='Methanol demand shares'!B6*'Indirect NH3 demand sources'!B$4 -> 0 | C6: ='Methanol demand shares'!C6*'Indirect NH3 demand sources'!C$4 -> 0 | D6: ='Methanol demand shares'!D6*'Indirect NH3 demand sources'!D$4 -> 0 | E6: ='Methanol demand shares'!E6*'Indirect NH3 demand sources'!E$4 -> 0 | F6: ='Methanol demand shares'!F6*'Indirect NH3 demand sources'!F$4 -> 0 | G6: ='Methanol demand shares'!G6*'Indirect NH3 demand sources'!G$4 -> 0 | H6: ='Methanol demand shares'!H6*'Indirect NH3 demand sources'!H$4 -> 0 | I6: ='Methanol demand shares'!I6*'Indirect NH3 demand sources'!I$4 -> 0 | ... AP6: ='Methanol demand shares'!AP6*'Indirect NH3 demand sources'!AP$4 -> 0.01073376
A7: Dan_ba_T1-5; 5 Spain (ES); sum of FUTI | B7: ='Methanol demand shares'!B7*'Indirect NH3 demand sources'!B$4 -> 0 | C7: ='Methanol demand shares'!C7*'Indirect NH3 demand sources'!C$4 -> 0 | D7: ='Methanol demand shares'!D7*'Indirect NH3 demand sources'!D$4 -> 0 | E7: ='Methanol demand shares'!E7*'Indirect NH3 demand sources'!E$4 -> 0 | F7: ='Methanol demand shares'!F7*'Indirect NH3 demand sources'!F$4 -> 0 | G7: ='Methanol demand shares'!G7*'Indirect NH3 demand sources'!G$4 -> 0 | H7: ='Methanol demand shares'!H7*'Indirect NH3 demand sources'!H$4 -> 0 | I7: ='Methanol demand shares'!I7*'Indirect NH3 demand sources'!I$4 -> 0 | ... AP7: ='Methanol demand shares'!AP7*'Indirect NH3 demand sources'!AP$4 -> 0.087546924
A8: Dan_ba_T1-5; 6 France (FR); sum of FUTI | B8: ='Methanol demand shares'!B8*'Indirect NH3 demand sources'!B$4 -> 0 | C8: ='Methanol demand shares'!C8*'Indirect NH3 demand sources'!C$4 -> 0 | D8: ='Methanol demand shares'!D8*'Indirect NH3 demand sources'!D$4 -> 0 | E8: ='Methanol demand shares'!E8*'Indirect NH3 demand sources'!E$4 -> 0 | F8: ='Methanol demand shares'!F8*'Indirect NH3 demand sources'!F$4 -> 0 | G8: ='Methanol demand shares'!G8*'Indirect NH3 demand sources'!G$4 -> 0 | H8: ='Methanol demand shares'!H8*'Indirect NH3 demand sources'!H$4 -> 0 | I8: ='Methanol demand shares'!I8*'Indirect NH3 demand sources'!I$4 -> 0 | ... AP8: ='Methanol demand shares'!AP8*'Indirect NH3 demand sources'!AP$4 -> 0.071378424
A9: Dan_ba_T1-5; 7 Ireland (IE); sum of FUTI | B9: ='Methanol demand shares'!B9*'Indirect NH3 demand sources'!B$4 -> 0 | C9: ='Methanol demand shares'!C9*'Indirect NH3 demand sources'!C$4 -> 0 | D9: ='Methanol demand shares'!D9*'Indirect NH3 demand sources'!D$4 -> 0 | E9: ='Methanol demand shares'!E9*'Indirect NH3 demand sources'!E$4 -> 0 | F9: ='Methanol demand shares'!F9*'Indirect NH3 demand sources'!F$4 -> 0 | G9: ='Methanol demand shares'!G9*'Indirect NH3 demand sources'!G$4 -> 0 | H9: ='Methanol demand shares'!H9*'Indirect NH3 demand sources'!H$4 -> 0 | I9: ='Methanol demand shares'!I9*'Indirect NH3 demand sources'!I$4 -> 0 | ... AP9: ='Methanol demand shares'!AP9*'Indirect NH3 demand sources'!AP$4 -> 0.16014197
A10: Dan_ba_T1-5; 8 Italy (IT); sum of FUTI | B10: ='Methanol demand shares'!B10*'Indirect NH3 demand sources'!B$4 -> 0 | C10: ='Methanol demand shares'!C10*'Indirect NH3 demand sources'!C$4 -> 0 | D10: ='Methanol demand shares'!D10*'Indirect NH3 demand sources'!D$4 -> 0 | E10: ='Methanol demand shares'!E10*'Indirect NH3 demand sources'!E$4 -> 0 | F10: ='Methanol demand shares'!F10*'Indirect NH3 demand sources'!F$4 -> 0 | G10: ='Methanol demand shares'!G10*'Indirect NH3 demand sources'!G$4 -> 0 | H10: ='Methanol demand shares'!H10*'Indirect NH3 demand sources'!H$4 -> 0 | I10: ='Methanol demand shares'!I10*'Indirect NH3 demand sources'!I$4 -> 0 | ... AP10: ='Methanol demand shares'!AP10*'Indirect NH3 demand sources'!AP$4 -> 0.11664328
A11: Dan_ba_T1-5; 9 Luxembourg (LX); sum of FUTI | B11: ='Methanol demand shares'!B11*'Indirect NH3 demand sources'!B$4 -> 0 | C11: ='Methanol demand shares'!C11*'Indirect NH3 demand sources'!C$4 -> 0 | D11: ='Methanol demand shares'!D11*'Indirect NH3 demand sources'!D$4 -> 0 | E11: ='Methanol demand shares'!E11*'Indirect NH3 demand sources'!E$4 -> 0 | F11: ='Methanol demand shares'!F11*'Indirect NH3 demand sources'!F$4 -> 0 | G11: ='Methanol demand shares'!G11*'Indirect NH3 demand sources'!G$4 -> 0 | H11: ='Methanol demand shares'!H11*'Indirect NH3 demand sources'!H$4 -> 0 | I11: ='Methanol demand shares'!I11*'Indirect NH3 demand sources'!I$4 -> 0 | ... AP11: ='Methanol demand shares'!AP11*'Indirect NH3 demand sources'!AP$4 -> 0.0019577772
A12: Dan_ba_T1-5; 10 Netherlands (NL); sum of FUTI | B12: ='Methanol demand shares'!B12*'Indirect NH3 demand sources'!B$4 -> 0 | C12: ='Methanol demand shares'!C12*'Indirect NH3 demand sources'!C$4 -> 0 | D12: ='Methanol demand shares'!D12*'Indirect NH3 demand sources'!D$4 -> 0 | E12: ='Methanol demand shares'!E12*'Indirect NH3 demand sources'!E$4 -> 0 | F12: ='Methanol demand shares'!F12*'Indirect NH3 demand sources'!F$4 -> 0 | G12: ='Methanol demand shares'!G12*'Indirect NH3 demand sources'!G$4 -> 0 | H12: ='Methanol demand shares'!H12*'Indirect NH3 demand sources'!H$4 -> 0 | I12: ='Methanol demand shares'!I12*'Indirect NH3 demand sources'!I$4 -> 0 | ... AP12: ='Methanol demand shares'!AP12*'Indirect NH3 demand sources'!AP$4 -> 0.1628208
A13: Dan_ba_T1-5; 11 Austria (AT); sum of FUTI | B13: ='Methanol demand shares'!B13*'Indirect NH3 demand sources'!B$4 -> 0 | C13: ='Methanol demand shares'!C13*'Indirect NH3 demand sources'!C$4 -> 0 | D13: ='Methanol demand shares'!D13*'Indirect NH3 demand sources'!D$4 -> 0 | E13: ='Methanol demand shares'!E13*'Indirect NH3 demand sources'!E$4 -> 0 | F13: ='Methanol demand shares'!F13*'Indirect NH3 demand sources'!F$4 -> 0 | G13: ='Methanol demand shares'!G13*'Indirect NH3 demand sources'!G$4 -> 0 | H13: ='Methanol demand shares'!H13*'Indirect NH3 demand sources'!H$4 -> 0 | I13: ='Methanol demand shares'!I13*'Indirect NH3 demand sources'!I$4 -> 0 | ... AP13: ='Methanol demand shares'!AP13*'Indirect NH3 demand sources'!AP$4 -> 0.038657592
A14: Dan_ba_T1-5; 12 Portugal (PT); sum of FUTI | B14: ='Methanol demand shares'!B14*'Indirect NH3 demand sources'!B$4 -> 0 | C14: ='Methanol demand shares'!C14*'Indirect NH3 demand sources'!C$4 -> 0 | D14: ='Methanol demand shares'!D14*'Indirect NH3 demand sources'!D$4 -> 0 | E14: ='Methanol demand shares'!E14*'Indirect NH3 demand sources'!E$4 -> 0 | F14: ='Methanol demand shares'!F14*'Indirect NH3 demand sources'!F$4 -> 0 | G14: ='Methanol demand shares'!G14*'Indirect NH3 demand sources'!G$4 -> 0 | H14: ='Methanol demand shares'!H14*'Indirect NH3 demand sources'!H$4 -> 0 | I14: ='Methanol demand shares'!I14*'Indirect NH3 demand sources'!I$4 -> 0 | ... AP14: ='Methanol demand shares'!AP14*'Indirect NH3 demand sources'!AP$4 -> 0.01207638
... A73: Dan_ba_T1-5; 71 Pakistan (PK); sum of FUTI | B73: ='Methanol demand shares'!B73*'Indirect NH3 demand sources'!B$4 -> 0 | C73: ='Methanol demand shares'!C73*'Indirect NH3 demand sources'!C$4 -> 0 | D73: ='Methanol demand shares'!D73*'Indirect NH3 demand sources'!D$4 -> 0 | E73: ='Methanol demand shares'!E73*'Indirect NH3 demand sources'!E$4 -> 0 | F73: ='Methanol demand shares'!F73*'Indirect NH3 demand sources'!F$4 -> 0 | G73: ='Methanol demand shares'!G73*'Indirect NH3 demand sources'!G$4 -> 0 | H73: ='Methanol demand shares'!H73*'Indirect NH3 demand sources'!H$4 -> 0 | I73: ='Methanol demand shares'!I73*'Indirect NH3 demand sources'!I$4 -> 0 | ... AP73: ='Methanol demand shares'!AP73*'Indirect NH3 demand sources'!AP$4 -> 0.010909548

Sheet Total exports
A1: QEX - product exports outside EU
A2: time | B2: 2010 | C2: 2011 | D2: 2012 | E2: 2013 | F2: 2014 | G2: 2015 | H2: 2016 | I2: 2017 | J2: 2018 | K2: 2019 | L2: 2020 | M2: 2021 | N2: 2022 | O2: 2023 | P2: 2024 | Q2: 2025 | R2: 2026 | S2: 2027 | T2: 2028 | U2: 2029 | V2: 2030 | W2: 2031 | X2: 2032 | Y2: 2033 | Z2: 2034 | AA2: 2035 | AB2: 2036 | AC2: 2037 | AD2: 2038 | AE2: 2039 | AF2: 2040 | AG2: 2041 | AH2: 2042 | AI2: 2043 | AJ2: 2044 | AK2: 2045 | AL2: 2046 | AM2: 2047 | AN2: 2048 | AO2: 2049 | AP2: 2050
A3: Dan_ba; 1 Belgium (BE); sum of YTI | B3: 83904.376 | C3: 92441.947 | D3: 96796.096 | E3: 95856.42 | F3: 97689.882 | G3: 96988.659 | H3: 104821.88 | I3: 113168.47 | J3: 114192.1 | K3: 117839.24 | L3: 108242.09 | M3: 133428.17 | N3: 158465.63 | O3: 158016.14 | P3: 159883.47 | Q3: 164233.56 | R3: 166420.7 | S3: 168437.48 | T3: 170269.22 | U3: 171964.59 | V3: 173946.73 | W3: 175837.8 | X3: 177714.43 | Y3: 179655.57 | Z3: 181749.86 | AA3: 184006.54 | AB3: 186435.69 | AC3: 189043.04 | AD3: 191823.55 | AE3: 194791.32 | AF3: 198011.58 | AG3: 201214.82 | AH3: 204420.66 | AI3: 207561.29 | AJ3: 210661.65 | AK3: 213730 | AL3: 216745.32 | AM3: 219713.6 | AN3: 222660.23 | AO3: 225629.22 | AP3: 228594.43
A4: Dan_ba; 2 Denmark (DK); sum of YTI | B4: 51745.172 | C4: 57597.1 | D4: 63124.999 | E4: 64490.9 | F4: 66691.814 | G4: 71209.654 | H4: 67453.775 | I4: 73137.118 | J4: 77866.801 | K4: 82662.765 | L4: 78150.268 | M4: 91679.152 | N4: 121347.01 | O4: 130346.23 | P4: 133347.68 | Q4: 135986.3 | R4: 137006.75 | S4: 137788.41 | T4: 138622.51 | U4: 139610.57 | V4: 140834.18 | W4: 142306.21 | X4: 143882.9 | Y4: 145494.6 | Z4: 147203.52 | AA4: 149014.53 | AB4: 150949.46 | AC4: 152994.55 | AD4: 155171.01 | AE4: 157498.37 | AF4: 160014.46 | AG4: 162599.58 | AH4: 165231.14 | AI4: 167909.51 | AJ4: 170659.51 | AK4: 173437.53 | AL4: 176252.24 | AM4: 179117.83 | AN4: 182017.18 | AO4: 184957.28 | AP4: 187928.02
A5: Dan_ba; 3 Germany (DE); sum of YTI | B5: 458307.07 | C5: 517699.41 | D5: 572891.61 | E5: 568180.54 | F5: 581660.12 | G5: 620429.22 | H5: 621182.54 | I5: 664409.29 | J5: 678238.21 | K5: 697453.64 | L5: 630392.6 | M5: 728571.6 | N5: 840994.32 | O5: 836861.16 | P5: 852331.29 | Q5: 877926.38 | R5: 886649.15 | S5: 895244.78 | T5: 903129.67 | U5: 910326.32 | V5: 916995.41 | W5: 923168.82 | X5: 929816.68 | Y5: 937264.97 | Z5: 945773.05 | AA5: 955540.71 | AB5: 966826.3 | AC5: 979562.3 | AD5: 993390.66 | AE5: 1008123.1 | AF5: 1024072 | AG5: 1040379.3 | AH5: 1056922.7 | AI5: 1073298.4 | AJ5: 1089597.4 | AK5: 1105660.8 | AL5: 1121489.6 | AM5: 1137013.2 | AN5: 1152266.1 | AO5: 1167320.1 | AP5: 1182115.8
A6: Dan_ba; 4 Greece (EL); sum of YTI | B6: 24309.611 | C6: 24699 | D6: 27889.852 | E6: 26354.952 | F6: 26690.069 | G6: 27221.391 | H6: 25019.136 | I6: 30091.495 | J6: 34790.472 | K6: 36543.144 | L6: 26291.466 | M6: 36924.516 | N6: 50448.788 | O6: 52992.354 | P6: 55555.995 | Q6: 57581.04 | R6: 58284.977 | S6: 58948.138 | T6: 59517.051 | U6: 59991.731 | V6: 60387.528 | W6: 60646.233 | X6: 60895.353 | Y6: 61197.161 | Z6: 61551.468 | AA6: 61976.777 | AB6: 62457 | AC6: 63012.527 | AD6: 63624.976 | AE6: 64295.19 | AF6: 65050.974 | AG6: 65795.569 | AH6: 66571.415 | AI6: 67357.372 | AJ6: 68167.573 | AK6: 68995.736 | AL6: 69828.38 | AM6: 70688.347 | AN6: 71579.228 | AO6: 72458.249 | AP6: 73328.408
A7: Dan_ba; 5 Spain (ES); sum of YTI | B7: 119873.96 | C7: 136004.53 | D7: 141240.66 | E7: 143669.64 | F7: 213204.3 | G7: 224109.42 | H7: 234268.14 | I7: 254357.14 | J7: 264713.57 | K7: 272016.87 | L7: 215490.64 | M7: 261358.8 | N7: 344310.9 | O7: 351059.7 | P7: 361197.09 | Q7: 373781.12 | R7: 379162.37 | S7: 384271.18 | T7: 388588.85 | U7: 392576.73 | V7: 396165.45 | W7: 399270.34 | X7: 402055.64 | Y7: 405252 | Z7: 409134.88 | AA7: 413420.35 | AB7: 418301.67 | AC7: 424009.21 | AD7: 430193.61 | AE7: 437033.64 | AF7: 444331.74 | AG7: 451303.31 | AH7: 458086.33 | AI7: 464712.29 | AJ7: 471284.31 | AK7: 477805.99 | AL7: 484371.86 | AM7: 491089.6 | AN7: 498020.57 | AO7: 504871.34 | AP7: 511706.74
A8: Dan_ba; 6 France (FR); sum of YTI | B8: 225072.16 | C8: 242212 | D8: 263987 | E8: 271962 | F8: 274428 | G8: 289900.2 | H8: 285070.39 | I8: 303382.94 | J8: 319765.5 | K8: 328557.78 | L8: 270240.72 | M8: 320627.32 | N8: 390552.07 | O8: 396548.35 | P8: 405613.16 | Q8: 417483.92 | R8: 419944.26 | S8: 421969.66 | T8: 424027.52 | U8: 426194.75 | V8: 428488.85 | W8: 430936.88 | X8: 433454.05 | Y8: 436238.11 | Z8: 439871.13 | AA8: 443289.97 | AB8: 447020.96 | AC8: 451459.21 | AD8: 456676.91 | AE8: 463500.61 | AF8: 470067.07 | AG8: 476766.93 | AH8: 483904.03 | AI8: 491323.69 | AJ8: 498678.8 | AK8: 506014.62 | AL8: 513213.26 | AM8: 520416.58 | AN8: 527581.16 | AO8: 534729.63 | AP8: 541880.31
A9: Dan_ba; 7 Ireland (IE); sum of YTI | B9: 69022.507 | C9: 73160.669 | D9: 75435.569 | E9: 82135.455 | F9: 98153.509 | G9: 175299.45 | H9: 180357.35 | I9: 205214.71 | J9: 218558.73 | K9: 248585.75 | L9: 271856.22 | M9: 316362.38 | N9: 378231.46 | O9: 372978.17 | P9: 386545.54 | Q9: 403150.06 | R9: 423979.75 | S9: 444728.4 | T9: 464294.52 | U9: 482389.72 | V9: 498537.56 | W9: 512226.73 | X9: 522749.1 | Y9: 532940.34 | Z9: 543262.23 | AA9: 553747.67 | AB9: 564404.55 | AC9: 575243.91 | AD9: 586057.83 | AE9: 596745.46 | AF9: 607237.03 | AG9: 617274.39 | AH9: 626954.35 | AI9: 636231.6 | AJ9: 645136.94 | AK9: 653768.4 | AL9: 662088.35 | AM9: 670339.98 | AN9: 678758.82 | AO9: 687381.31 | AP9: 696259.92
A10: Dan_ba; 8 Italy (IT); sum of YTI | B10: 174707.57 | C10: 196150.98 | D10: 215427.39 | E10: 217181.53 | F10: 218207.63 | G10: 223707.41 | H10: 223161.34 | I10: 237734.02 | J10: 242077.02 | K10: 247477.52 | L10: 213112.29 | M10: 254724.87 | N10: 310772.4 | O10: 312545.24 | P10: 320464.01 | Q10: 330464.46 | R10: 333733.15 | S10: 336683.77 | T10: 339437.92 | U10: 341844.55 | V10: 344013.42 | W10: 345878.22 | X10: 347621.09 | Y10: 349646.24 | Z10: 352025.86 | AA10: 354816.09 | AB10: 358082.32 | AC10: 361822.89 | AD10: 365950.07 | AE10: 370485.16 | AF10: 375595.51 | AG10: 380809.92 | AH10: 386113.66 | AI10: 391498.48 | AJ10: 396997.43 | AK10: 402564.5 | AL10: 408245.12 | AM10: 414073.33 | AN10: 420080.35 | AO10: 426118.49 | AP10: 432197.01
A11: Dan_ba; 9 Luxembourg (LX); sum of YTI | B11: 17537.809 | C11: 18384.144 | D11: 20246.442 | E11: 22635.41 | F11: 23907.184 | G11: 27457.841 | H11: 27434.767 | I11: 28156.626 | J11: 28556.318 | K11: 30991.517 | L11: 31519.642 | M11: 37105.819 | N11: 39393.424 | O11: 38972.57 | P11: 40048.096 | Q11: 41793.209 | R11: 43286.261 | S11: 44848.79 | T11: 46233.701 | U11: 47512.756 | V11: 48720.562 | W11: 49873.243 | X11: 50993.081 | Y11: 52128.903 | Z11: 53291.956 | AA11: 54515.5 | AB11: 55795.87 | AC11: 57123.934 | AD11: 58517.484 | AE11: 59994.837 | AF11: 61548.35 | AG11: 63086.493 | AH11: 64598.169 | AI11: 66072.318 | AJ11: 67513.326 | AK11: 68903.637 | AL11: 70247.152 | AM11: 71545.728 | AN11: 72767.901 | AO11: 73927.816 | AP11: 75023.127
A12: Dan_ba; 10 Netherlands (NL); sum of YTI | B12: 129031.93 | C12: 139317.93 | D12: 155535.75 | E12: 158127.44 | F12: 164134.96 | G12: 181670.61 | H12: 175618.13 | I12: 195089.38 | J12: 212641.4 | K12: 217714.77 | L12: 202249.72 | M12: 237547.58 | N12: 291548.92 | O12: 293057.19 | P12: 296868.02 | Q12: 302694.83 | R12: 306158.04 | S12: 309216.58 | T12: 312009.63 | U12: 314705.21 | V12: 317264.57 | W12: 319608.26 | X12: 322009.19 | Y12: 324597.15 | Z12: 327479.29 | AA12: 330673.61 | AB12: 334221.7 | AC12: 338180.42 | AD12: 342557.41 | AE12: 347536.84 | AF12: 353152.71 | AG12: 359012.45 | AH12: 365113.91 | AI12: 371346.16 | AJ12: 377697.88 | AK12: 384111.43 | AL12: 390585.05 | AM12: 397073.7 | AN12: 403537.68 | AO12: 410012.66 | AP12: 416495.34
A13: Dan_ba; 11 Austria (AT); sum of YTI | B13: 37323.004 | C13: 42328.576 | D13: 42036.781 | E13: 42800.552 | F13: 43669.265 | G13: 48420.264 | H13: 48927.681 | I13: 48258.412 | J13: 50710.787 | K13: 52554.948 | L13: 46628.774 | M13: 53809.798 | N13: 65890.992 | O13: 66355.639 | P13: 68155.458 | Q13: 70399.876 | R13: 71348.552 | S13: 72311.548 | T13: 73306.039 | U13: 74288.612 | V13: 75246.347 | W13: 76157.177 | X13: 77102.67 | Y13: 78064.402 | Z13: 79069.252 | AA13: 80118.079 | AB13: 81229.814 | AC13: 82400.272 | AD13: 83639.494 | AE13: 84942.538 | AF13: 86330.452 | AG13: 87729.264 | AH13: 89122.104 | AI13: 90493.852 | AJ13: 91846.46 | AK13: 93176.117 | AL13: 94482.181 | AM13: 95759.919 | AN13: 97009.337 | AO13: 98254.735 | AP13: 99483.831
... A73: Dan_ba; 71 Pakistan (PK); sum of YTI | B73: 18045.878 | C73: 18487.75 | D73: 15682.503 | E73: 17878.97 | F73: 17596.488 | G73: 16499.665 | H73: 16239.544 | I73: 16090.733 | J73: 18130.4 | K73: 18696.069 | L73: 18519.702 | M73: 19583.11 | N73: 20751.718 | O73: 21478.028 | P73: 22533.626 | Q73: 23659.663 | R73: 24936.511 | S73: 26183.101 | T73: 28319.088 | U73: 30060.683 | V73: 31141.896 | W73: 32628.952 | X73: 34157.861 | Y73: 35728.198 | Z73: 37342.435 | AA73: 39000.769 | AB73: 40705.27 | AC73: 42454.444 | AD73: 44252.883 | AE73: 46098.641 | AF73: 47990.932 | AG73: 49935.929 | AH73: 51931.661 | AI73: 53980.109 | AJ73: 56080.367 | AK73: 58233.175 | AL73: 60442.371 | AM73: 62707.752 | AN73: 65029.528 | AO73: 67409.302 | AP73: 69844.567

Sheet Export shares
A1: QEX - product exports outside EU
A2: time | B2: 2010 | C2: 2011 | D2: 2012 | E2: 2013 | F2: 2014 | G2: 2015 | H2: 2016 | I2: 2017 | J2: 2018 | K2: 2019 | L2: 2020 | M2: 2021 | N2: 2022 | O2: 2023 | P2: 2024 | Q2: 2025 | R2: 2026 | S2: 2027 | T2: 2028 | U2: 2029 | V2: 2030 | W2: 2031 | X2: 2032 | Y2: 2033 | Z2: 2034 | AA2: 2035 | AB2: 2036 | AC2: 2037 | AD2: 2038 | AE2: 2039 | AF2: 2040 | AG2: 2041 | AH2: 2042 | AI2: 2043 | AJ2: 2044 | AK2: 2045 | AL2: 2046 | AM2: 2047 | AN2: 2048 | AO2: 2049 | AP2: 2050
A3: Dan_ba; 1 Belgium (BE); sum of YTI | B3: ='Total exports'!B3/SUM('Total exports'!B$3:B$73) -> 0.0077975571 | C3: ='Total exports'!C3/SUM('Total exports'!C$3:C$73) -> 0.0079656749 | D3: ='Total exports'!D3/SUM('Total exports'!D$3:D$73) -> 0.0080547461 | E3: ='Total exports'!E3/SUM('Total exports'!E$3:E$73) -> 0.0077028152 | F3: ='Total exports'!F3/SUM('Total exports'!F$3:F$73) -> 0.0074895117 | G3: ='Total exports'!G3/SUM('Total exports'!G$3:G$73) -> 0.0073310011 | H3: ='Total exports'!H3/SUM('Total exports'!H$3:H$73) -> 0.007871581 | I3: ='Total exports'!I3/SUM('Total exports'!I$3:I$73) -> 0.0080490869 | ... AP3: ='Total exports'!AP3/SUM('Total exports'!AP$3:AP$73) -> 0.006574017
A4: Dan_ba; 2 Denmark (DK); sum of YTI | B4: ='Total exports'!B4/SUM('Total exports'!B$3:B$73) -> 0.0048088782 | C4: ='Total exports'!C4/SUM('Total exports'!C$3:C$73) -> 0.0049631124 | D4: ='Total exports'!D4/SUM('Total exports'!D$3:D$73) -> 0.0052528549 | E4: ='Total exports'!E4/SUM('Total exports'!E$3:E$73) -> 0.0051823497 | F4: ='Total exports'!F4/SUM('Total exports'!F$3:F$73) -> 0.0051130077 | G4: ='Total exports'!G4/SUM('Total exports'!G$3:G$73) -> 0.0053824648 | H4: ='Total exports'!H4/SUM('Total exports'!H$3:H$73) -> 0.0050654294 | I4: ='Total exports'!I4/SUM('Total exports'!I$3:I$73) -> 0.0052018642 | ... AP4: ='Total exports'!AP4/SUM('Total exports'!AP$3:AP$73) -> 0.005404515
A5: Dan_ba; 3 Germany (DE); sum of YTI | B5: ='Total exports'!B5/SUM('Total exports'!B$3:B$73) -> 0.042592242 | C5: ='Total exports'!C5/SUM('Total exports'!C$3:C$73) -> 0.044609891 | D5: ='Total exports'!D5/SUM('Total exports'!D$3:D$73) -> 0.047672341 | E5: ='Total exports'!E5/SUM('Total exports'!E$3:E$73) -> 0.045657762 | F5: ='Total exports'!F5/SUM('Total exports'!F$3:F$73) -> 0.044593669 | G5: ='Total exports'!G5/SUM('Total exports'!G$3:G$73) -> 0.046895867 | H5: ='Total exports'!H5/SUM('Total exports'!H$3:H$73) -> 0.046647593 | I5: ='Total exports'!I5/SUM('Total exports'!I$3:I$73) -> 0.04725599 | ... AP5: ='Total exports'!AP5/SUM('Total exports'!AP$3:AP$73) -> 0.033995794
A6: Dan_ba; 4 Greece (EL); sum of YTI | B6: ='Total exports'!B6/SUM('Total exports'!B$3:B$73) -> 0.0022591858 | C6: ='Total exports'!C6/SUM('Total exports'!C$3:C$73) -> 0.0021283001 | D6: ='Total exports'!D6/SUM('Total exports'!D$3:D$73) -> 0.0023208134 | E6: ='Total exports'!E6/SUM('Total exports'!E$3:E$73) -> 0.0021178271 | F6: ='Total exports'!F6/SUM('Total exports'!F$3:F$73) -> 0.002046226 | G6: ='Total exports'!G6/SUM('Total exports'!G$3:G$73) -> 0.0020575606 | H6: ='Total exports'!H6/SUM('Total exports'!H$3:H$73) -> 0.0018788076 | I6: ='Total exports'!I6/SUM('Total exports'!I$3:I$73) -> 0.002140252 | ... AP6: ='Total exports'!AP6/SUM('Total exports'!AP$3:AP$73) -> 0.0021088099
A7: Dan_ba; 5 Spain (ES); sum of YTI | B7: ='Total exports'!B7/SUM('Total exports'!B$3:B$73) -> 0.01114035 | C7: ='Total exports'!C7/SUM('Total exports'!C$3:C$73) -> 0.01171944 | D7: ='Total exports'!D7/SUM('Total exports'!D$3:D$73) -> 0.011753136 | E7: ='Total exports'!E7/SUM('Total exports'!E$3:E$73) -> 0.011544983 | F7: ='Total exports'!F7/SUM('Total exports'!F$3:F$73) -> 0.016345563 | G7: ='Total exports'!G7/SUM('Total exports'!G$3:G$73) -> 0.016939572 | H7: ='Total exports'!H7/SUM('Total exports'!H$3:H$73) -> 0.017592325 | I7: ='Total exports'!I7/SUM('Total exports'!I$3:I$73) -> 0.018091105 | ... AP7: ='Total exports'!AP7/SUM('Total exports'!AP$3:AP$73) -> 0.014715883
A8: Dan_ba; 6 France (FR); sum of YTI | B8: ='Total exports'!B8/SUM('Total exports'!B$3:B$73) -> 0.020916823 | C8: ='Total exports'!C8/SUM('Total exports'!C$3:C$73) -> 0.020871283 | D8: ='Total exports'!D8/SUM('Total exports'!D$3:D$73) -> 0.021967294 | E8: ='Total exports'!E8/SUM('Total exports'!E$3:E$73) -> 0.02185428 | F8: ='Total exports'!F8/SUM('Total exports'!F$3:F$73) -> 0.021039351 | G8: ='Total exports'!G8/SUM('Total exports'!G$3:G$73) -> 0.021912445 | H8: ='Total exports'!H8/SUM('Total exports'!H$3:H$73) -> 0.021407311 | I8: ='Total exports'!I8/SUM('Total exports'!I$3:I$73) -> 0.021578056 | ... AP8: ='Total exports'!AP8/SUM('Total exports'!AP$3:AP$73) -> 0.015583627
A9: Dan_ba; 7 Ireland (IE); sum of YTI | B9: ='Total exports'!B9/SUM('Total exports'!B$3:B$73) -> 0.0064145276 | C9: ='Total exports'!C9/SUM('Total exports'!C$3:C$73) -> 0.0063042171 | D9: ='Total exports'!D9/SUM('Total exports'!D$3:D$73) -> 0.006277261 | E9: ='Total exports'!E9/SUM('Total exports'!E$3:E$73) -> 0.006600228 | F9: ='Total exports'!F9/SUM('Total exports'!F$3:F$73) -> 0.0075250563 | G9: ='Total exports'!G9/SUM('Total exports'!G$3:G$73) -> 0.013250213 | H9: ='Total exports'!H9/SUM('Total exports'!H$3:H$73) -> 0.013543903 | I9: ='Total exports'!I9/SUM('Total exports'!I$3:I$73) -> 0.014595859 | ... AP9: ='Total exports'!AP9/SUM('Total exports'!AP$3:AP$73) -> 0.020023343
A10: Dan_ba; 8 Italy (IT); sum of YTI | B10: ='Total exports'!B10/SUM('Total exports'!B$3:B$73) -> 0.016236248 | C10: ='Total exports'!C10/SUM('Total exports'!C$3:C$73) -> 0.016902229 | D10: ='Total exports'!D10/SUM('Total exports'!D$3:D$73) -> 0.017926476 | E10: ='Total exports'!E10/SUM('Total exports'!E$3:E$73) -> 0.017452239 | F10: ='Total exports'!F10/SUM('Total exports'!F$3:F$73) -> 0.016729149 | G10: ='Total exports'!G10/SUM('Total exports'!G$3:G$73) -> 0.016909186 | H10: ='Total exports'!H10/SUM('Total exports'!H$3:H$73) -> 0.016758261 | I10: ='Total exports'!I10/SUM('Total exports'!I$3:I$73) -> 0.016908789 | ... AP10: ='Total exports'!AP10/SUM('Total exports'!AP$3:AP$73) -> 0.012429308
A11: Dan_ba; 9 Luxembourg (LX); sum of YTI | B11: ='Total exports'!B11/SUM('Total exports'!B$3:B$73) -> 0.0016298562 | C11: ='Total exports'!C11/SUM('Total exports'!C$3:C$73) -> 0.0015841522 | D11: ='Total exports'!D11/SUM('Total exports'!D$3:D$73) -> 0.0016847782 | E11: ='Total exports'!E11/SUM('Total exports'!E$3:E$73) -> 0.0018189327 | F11: ='Total exports'!F11/SUM('Total exports'!F$3:F$73) -> 0.0018328729 | G11: ='Total exports'!G11/SUM('Total exports'!G$3:G$73) -> 0.002075433 | H11: ='Total exports'!H11/SUM('Total exports'!H$3:H$73) -> 0.002060209 | I11: ='Total exports'!I11/SUM('Total exports'!I$3:I$73) -> 0.0020026349 | ... AP11: ='Total exports'!AP11/SUM('Total exports'!AP$3:AP$73) -> 0.0021575474
A12: Dan_ba; 10 Netherlands (NL); sum of YTI | B12: ='Total exports'!B12/SUM('Total exports'!B$3:B$73) -> 0.011991434 | C12: ='Total exports'!C12/SUM('Total exports'!C$3:C$73) -> 0.012004955 | D12: ='Total exports'!D12/SUM('Total exports'!D$3:D$73) -> 0.012942681 | E12: ='Total exports'!E12/SUM('Total exports'!E$3:E$73) -> 0.01270678 | F12: ='Total exports'!F12/SUM('Total exports'!F$3:F$73) -> 0.012583603 | G12: ='Total exports'!G12/SUM('Total exports'!G$3:G$73) -> 0.013731785 | H12: ='Total exports'!H12/SUM('Total exports'!H$3:H$73) -> 0.013188013 | I12: ='Total exports'!I12/SUM('Total exports'!I$3:I$73) -> 0.013875697 | ... AP12: ='Total exports'!AP12/SUM('Total exports'!AP$3:AP$73) -> 0.011977752
A13: Dan_ba; 11 Austria (AT); sum of YTI | B13: ='Total exports'!B13/SUM('Total exports'!B$3:B$73) -> 0.0034685706 | C13: ='Total exports'!C13/SUM('Total exports'!C$3:C$73) -> 0.0036474316 | D13: ='Total exports'!D13/SUM('Total exports'!D$3:D$73) -> 0.0034980295 | E13: ='Total exports'!E13/SUM('Total exports'!E$3:E$73) -> 0.0034393601 | F13: ='Total exports'!F13/SUM('Total exports'!F$3:F$73) -> 0.0033479565 | G13: ='Total exports'!G13/SUM('Total exports'!G$3:G$73) -> 0.0036599022 | H13: ='Total exports'!H13/SUM('Total exports'!H$3:H$73) -> 0.0036742156 | I13: ='Total exports'!I13/SUM('Total exports'!I$3:I$73) -> 0.0034323707 | ... AP13: ='Total exports'!AP13/SUM('Total exports'!AP$3:AP$73) -> 0.0028609988
A14: Dan_ba; 12 Portugal (PT); sum of YTI | B14: ='Total exports'!B14/SUM('Total exports'!B$3:B$73) -> 0.0012933502 | C14: ='Total exports'!C14/SUM('Total exports'!C$3:C$73) -> 0.0013838474 | D14: ='Total exports'!D14/SUM('Total exports'!D$3:D$73) -> 0.0015908682 | E14: ='Total exports'!E14/SUM('Total exports'!E$3:E$73) -> 0.0016483483 | F14: ='Total exports'!F14/SUM('Total exports'!F$3:F$73) -> 0.001622047 | G14: ='Total exports'!G14/SUM('Total exports'!G$3:G$73) -> 0.0015836151 | H14: ='Total exports'!H14/SUM('Total exports'!H$3:H$73) -> 0.0015050024 | I14: ='Total exports'!I14/SUM('Total exports'!I$3:I$73) -> 0.0016060242 | ... AP14: ='Total exports'!AP14/SUM('Total exports'!AP$3:AP$73) -> 0.001285881
... A73: Dan_ba; 71 Pakistan (PK); sum of YTI | B73: ='Total exports'!B73/SUM('Total exports'!B$3:B$73) -> 0.001677073 | C73: ='Total exports'!C73/SUM('Total exports'!C$3:C$73) -> 0.0015930799 | D73: ='Total exports'!D73/SUM('Total exports'!D$3:D$73) -> 0.0013049966 | E73: ='Total exports'!E73/SUM('Total exports'!E$3:E$73) -> 0.0014367155 | F73: ='Total exports'!F73/SUM('Total exports'!F$3:F$73) -> 0.0013490558 | G73: ='Total exports'!G73/SUM('Total exports'!G$3:G$73) -> 0.0012471465 | H73: ='Total exports'!H73/SUM('Total exports'!H$3:H$73) -> 0.0012195057 | I73: ='Total exports'!I73/SUM('Total exports'!I$3:I$73) -> 0.0011444505 | ... AP73: ='Total exports'!AP73/SUM('Total exports'!AP$3:AP$73) -> 0.0020086201

Sheet NH3 for maritime industry
A1: Methanol demand
A2: time | B2: 2010 | C2: 2011 | D2: 2012 | E2: 2013 | F2: 2014 | G2: 2015 | H2: 2016 | I2: 2017 | J2: 2018 | K2: 2019 | L2: 2020 | M2: 2021 | N2: 2022 | O2: 2023 | P2: 2024 | Q2: 2025 | R2: 2026 | S2: 2027 | T2: 2028 | U2: 2029 | V2: 2030 | W2: 2031 | X2: 2032 | Y2: 2033 | Z2: 2034 | AA2: 2035 | AB2: 2036 | AC2: 2037 | AD2: 2038 | AE2: 2039 | AF2: 2040 | AG2: 2041 | AH2: 2042 | AI2: 2043 | AJ2: 2044 | AK2: 2045 | AL2: 2046 | AM2: 2047 | AN2: 2048 | AO2: 2049 | AP2: 2050
A3: Dan_ba_T1-5; 1 Belgium (BE); sum of FUTI | B3: ='Export shares'!B3*'Indirect NH3 demand sources'!B$3 -> 0 | C3: ='Export shares'!C3*'Indirect NH3 demand sources'!C$3 -> 0 | D3: ='Export shares'!D3*'Indirect NH3 demand sources'!D$3 -> 0 | E3: ='Export shares'!E3*'Indirect NH3 demand sources'!E$3 -> 0 | F3: ='Export shares'!F3*'Indirect NH3 demand sources'!F$3 -> 0 | G3: ='Export shares'!G3*'Indirect NH3 demand sources'!G$3 -> 0 | H3: ='Export shares'!H3*'Indirect NH3 demand sources'!H$3 -> 0 | I3: ='Export shares'!I3*'Indirect NH3 demand sources'!I$3 -> 0 | ... AP3: ='Export shares'!AP3*'Indirect NH3 demand sources'!AP$3 -> 1.1964711
A4: Dan_ba_T1-5; 2 Denmark (DK); sum of FUTI | B4: ='Export shares'!B4*'Indirect NH3 demand sources'!B$3 -> 0 | C4: ='Export shares'!C4*'Indirect NH3 demand sources'!C$3 -> 0 | D4: ='Export shares'!D4*'Indirect NH3 demand sources'!D$3 -> 0 | E4: ='Export shares'!E4*'Indirect NH3 demand sources'!E$3 -> 0 | F4: ='Export shares'!F4*'Indirect NH3 demand sources'!F$3 -> 0 | G4: ='Export shares'!G4*'Indirect NH3 demand sources'!G$3 -> 0 | H4: ='Export shares'!H4*'Indirect NH3 demand sources'!H$3 -> 0 | I4: ='Export shares'!I4*'Indirect NH3 demand sources'!I$3 -> 0 | ... AP4: ='Export shares'!AP4*'Indirect NH3 demand sources'!AP$3 -> 0.98362173
A5: Dan_ba_T1-5; 3 Germany (DE); sum of FUTI | B5: ='Export shares'!B5*'Indirect NH3 demand sources'!B$3 -> 0 | C5: ='Export shares'!C5*'Indirect NH3 demand sources'!C$3 -> 0 | D5: ='Export shares'!D5*'Indirect NH3 demand sources'!D$3 -> 0 | E5: ='Export shares'!E5*'Indirect NH3 demand sources'!E$3 -> 0 | F5: ='Export shares'!F5*'Indirect NH3 demand sources'!F$3 -> 0 | G5: ='Export shares'!G5*'Indirect NH3 demand sources'!G$3 -> 0 | H5: ='Export shares'!H5*'Indirect NH3 demand sources'!H$3 -> 0 | I5: ='Export shares'!I5*'Indirect NH3 demand sources'!I$3 -> 0 | ... AP5: ='Export shares'!AP5*'Indirect NH3 demand sources'!AP$3 -> 6.1872345
A6: Dan_ba_T1-5; 4 Greece (EL); sum of FUTI | B6: ='Export shares'!B6*'Indirect NH3 demand sources'!B$3 -> 0 | C6: ='Export shares'!C6*'Indirect NH3 demand sources'!C$3 -> 0 | D6: ='Export shares'!D6*'Indirect NH3 demand sources'!D$3 -> 0 | E6: ='Export shares'!E6*'Indirect NH3 demand sources'!E$3 -> 0 | F6: ='Export shares'!F6*'Indirect NH3 demand sources'!F$3 -> 0 | G6: ='Export shares'!G6*'Indirect NH3 demand sources'!G$3 -> 0 | H6: ='Export shares'!H6*'Indirect NH3 demand sources'!H$3 -> 0 | I6: ='Export shares'!I6*'Indirect NH3 demand sources'!I$3 -> 0 | ... AP6: ='Export shares'!AP6*'Indirect NH3 demand sources'!AP$3 -> 0.38380341
A7: Dan_ba_T1-5; 5 Spain (ES); sum of FUTI | B7: ='Export shares'!B7*'Indirect NH3 demand sources'!B$3 -> 0 | C7: ='Export shares'!C7*'Indirect NH3 demand sources'!C$3 -> 0 | D7: ='Export shares'!D7*'Indirect NH3 demand sources'!D$3 -> 0 | E7: ='Export shares'!E7*'Indirect NH3 demand sources'!E$3 -> 0 | F7: ='Export shares'!F7*'Indirect NH3 demand sources'!F$3 -> 0 | G7: ='Export shares'!G7*'Indirect NH3 demand sources'!G$3 -> 0 | H7: ='Export shares'!H7*'Indirect NH3 demand sources'!H$3 -> 0 | I7: ='Export shares'!I7*'Indirect NH3 demand sources'!I$3 -> 0 | ... AP7: ='Export shares'!AP7*'Indirect NH3 demand sources'!AP$3 -> 2.6782907
A8: Dan_ba_T1-5; 6 France (FR); sum of FUTI | B8: ='Export shares'!B8*'Indirect NH3 demand sources'!B$3 -> 0 | C8: ='Export shares'!C8*'Indirect NH3 demand sources'!C$3 -> 0 | D8: ='Export shares'!D8*'Indirect NH3 demand sources'!D$3 -> 0 | E8: ='Export shares'!E8*'Indirect NH3 demand sources'!E$3 -> 0 | F8: ='Export shares'!F8*'Indirect NH3 demand sources'!F$3 -> 0 | G8: ='Export shares'!G8*'Indirect NH3 demand sources'!G$3 -> 0 | H8: ='Export shares'!H8*'Indirect NH3 demand sources'!H$3 -> 0 | I8: ='Export shares'!I8*'Indirect NH3 demand sources'!I$3 -> 0 | ... AP8: ='Export shares'!AP8*'Indirect NH3 demand sources'!AP$3 -> 2.8362202
A9: Dan_ba_T1-5; 7 Ireland (IE); sum of FUTI | B9: ='Export shares'!B9*'Indirect NH3 demand sources'!B$3 -> 0 | C9: ='Export shares'!C9*'Indirect NH3 demand sources'!C$3 -> 0 | D9: ='Export shares'!D9*'Indirect NH3 demand sources'!D$3 -> 0 | E9: ='Export shares'!E9*'Indirect NH3 demand sources'!E$3 -> 0 | F9: ='Export shares'!F9*'Indirect NH3 demand sources'!F$3 -> 0 | G9: ='Export shares'!G9*'Indirect NH3 demand sources'!G$3 -> 0 | H9: ='Export shares'!H9*'Indirect NH3 demand sources'!H$3 -> 0 | I9: ='Export shares'!I9*'Indirect NH3 demand sources'!I$3 -> 0 | ... AP9: ='Export shares'!AP9*'Indirect NH3 demand sources'!AP$3 -> 3.6442484
